Workbook

Sheet Notes
A1: Workforce Cost Variance Model — Notes & Methodology
A4: Scope | B4: 4 locations x 26 positions (Workforce Data, Transaction Data tabs).
A5: Scenario definitions
A6: Plan | B6: Original 2026 budget, set once at start of year.
A7: Prior Forecast | B7: Most recent 2026 re-forecast before the current one.
A8: Current Forecast | B8: Latest 2026 re-forecast (this model's "forecast" for variance purposes).
A9: Actual | B9: Only available for 2025 (last closed year). No 2026 actual exists yet in source data.
A11: Variance methodology
A12: Budget variance | B12: Current Forecast minus Plan. Negative = under budget (favorable). Positive = over budget (unfavorable).
A13: Re-forecast drift | B13: Current Forecast minus Prior Forecast. Shows whether the latest view is trending up or down vs the prior update.
A15: Efficiency methodology
A16: Primary ratio | B16: Labor $ per rental transaction, using 2025 Actual labor cost / 2025 Actual transactions (clean, both-actual basis).
A17: Secondary ratio | B17: 2026 Plan labor cost / 2026 Plan transactions, compared to the 2025 actual ratio to see if the budget assumes efficiency improves or erodes.

Sheet Location Summary
A5: Location | B5: FTE Current Forecast | C5: FTE Plan | D5: Labor $ Current Forecast | E5: Labor $ Plan | F5: Labor $ Prior Forecast
A6: Location 1 | B6: =SUMIF('Raw - Workforce'!$A$2:$A$105,A6,'Raw - Workforce'!$C$2:$C$105) -> 2271.6522 | C6: =SUMIF('Raw - Workforce'!$A$2:$A$105,A6,'Raw - Workforce'!$E$2:$E$105) -> 2417.9278 | D6: =SUMIF('Variance Analysis'!$A$2:$A$105,A6,'Variance Analysis'!$C$2:$C$105) -> 9574757.3 | E6: =SUMIF('Variance Analysis'!$A$2:$A$105,A6,'Variance Analysis'!$E$2:$E$105) -> 9859466.6 | F6: =SUMIF('Variance Analysis'!$A$2:$A$105,A6,'Variance Analysis'!$D$2:$D$105) -> 9656878.7
A7: Location 2 | B7: =SUMIF('Raw - Workforce'!$A$2:$A$105,A7,'Raw - Workforce'!$C$2:$C$105) -> 2379.988 | C7: =SUMIF('Raw - Workforce'!$A$2:$A$105,A7,'Raw - Workforce'!$E$2:$E$105) -> 2526.5351 | D7: =SUMIF('Variance Analysis'!$A$2:$A$105,A7,'Variance Analysis'!$C$2:$C$105) -> 8196137.9 | E7: =SUMIF('Variance Analysis'!$A$2:$A$105,A7,'Variance Analysis'!$E$2:$E$105) -> 8419827.5 | F7: =SUMIF('Variance Analysis'!$A$2:$A$105,A7,'Variance Analysis'!$D$2:$D$105) -> 8046167.5
A8: Location 3 | B8: =SUMIF('Raw - Workforce'!$A$2:$A$105,A8,'Raw - Workforce'!$C$2:$C$105) -> 2804.4606 | C8: =SUMIF('Raw - Workforce'!$A$2:$A$105,A8,'Raw - Workforce'!$E$2:$E$105) -> 2817.3301 | D8: =SUMIF('Variance Analysis'!$A$2:$A$105,A8,'Variance Analysis'!$C$2:$C$105) -> 10714422 | E8: =SUMIF('Variance Analysis'!$A$2:$A$105,A8,'Variance Analysis'!$E$2:$E$105) -> 10741859 | F8: =SUMIF('Variance Analysis'!$A$2:$A$105,A8,'Variance Analysis'!$D$2:$D$105) -> 10493876
A9: Location 4 | B9: =SUMIF('Raw - Workforce'!$A$2:$A$105,A9,'Raw - Workforce'!$C$2:$C$105) -> 3252.266 | C9: =SUMIF('Raw - Workforce'!$A$2:$A$105,A9,'Raw - Workforce'!$E$2:$E$105) -> 3455.8254 | D9: =SUMIF('Variance Analysis'!$A$2:$A$105,A9,'Variance Analysis'!$C$2:$C$105) -> 15038965 | E9: =SUMIF('Variance Analysis'!$A$2:$A$105,A9,'Variance Analysis'!$E$2:$E$105) -> 15368664 | F9: =SUMIF('Variance Analysis'!$A$2:$A$105,A9,'Variance Analysis'!$D$2:$D$105) -> 15035566
A10: Company Total | B10: =SUM(B6:B9) -> 10708.367 | C10: =SUM(C6:C9) -> 11217.618 | D10: =SUM(D6:D9) -> 43524282 | E10: =SUM(E6:E9) -> 44389818 | F10: =SUM(F6:F9) -> 43232489
A15: Location | B15: Var $ vs Plan | C15: Var % vs Plan | D15: Var $ vs Prior Forecast | E15: Var % vs Prior Forecast | F15: OT % of Salary Actual 2025 | G15: OT % of Salary Plan | H15: OT % of Salary Current Forecast
A16: Location 1 | B16: =D6-E6 -> -284709.23 | C16: =IFERROR(B16/E6,0) -> -0.028876738 | D16: =D6-F6 -> -82121.345 | E16: (.85%) | F16: =IFERROR(SUMIF('Raw - Workforce'!$A$2:$A$105,A6,'Raw - Workforce'!$N$2:$N$105)/SUMIF('Raw - Workforce'!$A$2:$A$105,A6,'Raw - Workforce'!$J$2:$J$105),0) -> 0.16532266 | G16: =IFERROR(SUMIF('Raw - Workforce'!$A$2:$A$105,A6,'Raw - Workforce'!$M$2:$M$105)/SUMIF('Raw - Workforce'!$A$2:$A$105,A6,'Raw - Workforce'!$I$2:$I$105),0) -> 0.14917003 | H16: =IFERROR(SUMIF('Raw - Workforce'!$A$2:$A$105,A6,'Raw - Workforce'!$K$2:$K$105)/SUMIF('Raw - Workforce'!$A$2:$A$105,A6,'Raw - Workforce'!$G$2:$G$105),0) -> 0.12452456
A17: Location 2 | B17: =D7-E7 -> -223689.51 | C17: =IFERROR(B17/E7,0) -> -0.026566994 | D17: =D7-F7 -> 149970.48 | E17: =D17/F7 -> 0.018638747 | F17: =IFERROR(SUMIF('Raw - Workforce'!$A$2:$A$105,A7,'Raw - Workforce'!$N$2:$N$105)/SUMIF('Raw - Workforce'!$A$2:$A$105,A7,'Raw - Workforce'!$J$2:$J$105),0) -> 0.10011764 | G17: =IFERROR(SUMIF('Raw - Workforce'!$A$2:$A$105,A7,'Raw - Workforce'!$M$2:$M$105)/SUMIF('Raw - Workforce'!$A$2:$A$105,A7,'Raw - Workforce'!$I$2:$I$105),0) -> 0.078056723 | H17: =IFERROR(SUMIF('Raw - Workforce'!$A$2:$A$105,A7,'Raw - Workforce'!$K$2:$K$105)/SUMIF('Raw - Workforce'!$A$2:$A$105,A7,'Raw - Workforce'!$G$2:$G$105),0) -> 0.077564782
A18: Location 3 | B18: =D8-E8 -> -27437.755 | C18: =IFERROR(B18/E8,0) -> -0.0025542836 | D18: =D8-F8 -> 220545.33 | E18: =D18/F8 -> 0.021016574 | F18: =IFERROR(SUMIF('Raw - Workforce'!$A$2:$A$105,A8,'Raw - Workforce'!$N$2:$N$105)/SUMIF('Raw - Workforce'!$A$2:$A$105,A8,'Raw - Workforce'!$J$2:$J$105),0) -> 0.11472845 | G18: =IFERROR(SUMIF('Raw - Workforce'!$A$2:$A$105,A8,'Raw - Workforce'!$M$2:$M$105)/SUMIF('Raw - Workforce'!$A$2:$A$105,A8,'Raw - Workforce'!$I$2:$I$105),0) -> 0.090821841 | H18: =IFERROR(SUMIF('Raw - Workforce'!$A$2:$A$105,A8,'Raw - Workforce'!$K$2:$K$105)/SUMIF('Raw - Workforce'!$A$2:$A$105,A8,'Raw - Workforce'!$G$2:$G$105),0) -> 0.085183002
A19: Location 4 | B19: =D9-E9 -> -329699.64 | C19: =IFERROR(B19/E9,0) -> -0.021452719 | D19: =D9-F9 -> 3398.46 | E19: =D19/F9 -> 0.00022602807 | F19: =IFERROR(SUMIF('Raw - Workforce'!$A$2:$A$105,A9,'Raw - Workforce'!$N$2:$N$105)/SUMIF('Raw - Workforce'!$A$2:$A$105,A9,'Raw - Workforce'!$J$2:$J$105),0) -> 0.10584733 | G19: =IFERROR(SUMIF('Raw - Workforce'!$A$2:$A$105,A9,'Raw - Workforce'!$M$2:$M$105)/SUMIF('Raw - Workforce'!$A$2:$A$105,A9,'Raw - Workforce'!$I$2:$I$105),0) -> 0.094684516 | H19: =IFERROR(SUMIF('Raw - Workforce'!$A$2:$A$105,A9,'Raw - Workforce'!$K$2:$K$105)/SUMIF('Raw - Workforce'!$A$2:$A$105,A9,'Raw - Workforce'!$G$2:$G$105),0) -> 0.086024099
A20: Company Total | B20: =SUM(B16:B19) -> -865536.13 | C20: =IFERROR(B20/E10,0) -> -0.019498529 | D20: =SUM(D16:D19) -> 291792.92 | E20: =IFERROR(D20/F10,0) -> 0.0067493898 | F20: =SUM('Raw - Workforce'!$N$2:$N$105)/SUM('Raw - Workforce'!$J$2:$J$105) -> 0.11935619 | G20: =SUM('Raw - Workforce'!$M$2:$M$105)/SUM('Raw - Workforce'!$I$2:$I$105) -> 0.10212213 | H20: =SUM('Raw - Workforce'!$K$2:$K$105)/SUM('Raw - Workforce'!$G$2:$G$105) -> 0.092428546

Sheet Efficiency Metrics
A2: Labor = Salary + Overtime = Total Labor Cost before benefits.
A5: Location | B5: Labor $ Actual 2025 | C5: Rental Transactions Actual 2025 | D5: Labor $/Transactions Actual 2025 (clean baseline) | E5: Labor $ Plan 2026 | F5: Rental Transactions Plan 2026 | G5: Labor $/Transactions Plan 2026
A6: ='Location Summary'!A6 -> Location 1 | B6: =SUMIF('Variance Analysis'!$A$2:$A$105,A6,'Variance Analysis'!$F$2:$F$105) -> 9144531.1 | C6: =INDEX('Raw - Transactions'!$E$2:$E$5,MATCH(A6,'Raw - Transactions'!$A$2:$A$5,0)) -> 402999 | D6: =IFERROR(B6/C6,0) -> 22.6912 | E6: ='Location Summary'!E6 -> 9859466.6 | F6: =INDEX('Raw - Transactions'!$D$2:$D$5,MATCH(A6,'Raw - Transactions'!$A$2:$A$5,0)) -> 425982.47 | G6: =IFERROR(E6/F6,0) -> 23.14524
A7: ='Location Summary'!A7 -> Location 2 | B7: =SUMIF('Variance Analysis'!$A$2:$A$105,A7,'Variance Analysis'!$F$2:$F$105) -> 7866269 | C7: =INDEX('Raw - Transactions'!$E$2:$E$5,MATCH(A7,'Raw - Transactions'!$A$2:$A$5,0)) -> 593382 | D7: =IFERROR(B7/C7,0) -> 13.256669 | E7: ='Location Summary'!E7 -> 8419827.5 | F7: =INDEX('Raw - Transactions'!$D$2:$D$5,MATCH(A7,'Raw - Transactions'!$A$2:$A$5,0)) -> 599083.3 | G7: =IFERROR(E7/F7,0) -> 14.054519
A8: ='Location Summary'!A8 -> Location 3 | B8: =SUMIF('Variance Analysis'!$A$2:$A$105,A8,'Variance Analysis'!$F$2:$F$105) -> 10464226 | C8: =INDEX('Raw - Transactions'!$E$2:$E$5,MATCH(A8,'Raw - Transactions'!$A$2:$A$5,0)) -> 602273 | D8: =IFERROR(B8/C8,0) -> 17.374557 | E8: ='Location Summary'!E8 -> 10741859 | F8: =INDEX('Raw - Transactions'!$D$2:$D$5,MATCH(A8,'Raw - Transactions'!$A$2:$A$5,0)) -> 625480.95 | G8: =IFERROR(E8/F8,0) -> 17.17376
A9: ='Location Summary'!A9 -> Location 4 | B9: =SUMIF('Variance Analysis'!$A$2:$A$105,A9,'Variance Analysis'!$F$2:$F$105) -> 14710693 | C9: =INDEX('Raw - Transactions'!$E$2:$E$5,MATCH(A9,'Raw - Transactions'!$A$2:$A$5,0)) -> 606371 | D9: =IFERROR(B9/C9,0) -> 24.260219 | E9: ='Location Summary'!E9 -> 15368664 | F9: =INDEX('Raw - Transactions'!$D$2:$D$5,MATCH(A9,'Raw - Transactions'!$A$2:$A$5,0)) -> 629076.38 | G9: =IFERROR(E9/F9,0) -> 24.430522
A10: Company Total | B10: =SUM(B6:B9) -> 42185720 | C10: =SUM(C6:C9) -> 2205025 | D10: =IFERROR(B10/C10,0) -> 19.131629 | E10: =SUM(E6:E9) -> 44389818 | F10: =SUM(F6:F9) -> 2279623.1 | G10: =IFERROR(E10/F10,0) -> 19.472437

Sheet Top Movers
A9: Top 8 Favorable (largest cost savings vs Plan)
A10: Location | B10: Position | C10: Labor $ Current Forecast | D10: Labor $ Plan | E10: Var $ vs Plan | F10: FTE Var vs Plan
A11: ='[1]Variance Analysis'!A55 -> Location 3 | B11: ='[1]Variance Analysis'!B55 -> Position B | C11: ='[1]Variance Analysis'!C55 -> 1445020.5 | D11: ='[1]Variance Analysis'!E55 -> 1706992.9 | E11: ='[1]Variance Analysis'!G55 -> -261972.36 | F11: ='[1]Variance Analysis'!J55 -> -82.074351
A12: ='[1]Variance Analysis'!A61 -> Location 3 | B12: ='[1]Variance Analysis'!B61 -> Position H | C12: ='[1]Variance Analysis'!C61 -> 1252895 | D12: ='[1]Variance Analysis'!E61 -> 1457336.4 | E12: ='[1]Variance Analysis'!G61 -> -204441.42 | F12: ='[1]Variance Analysis'!J61 -> -43.626628
A13: ='[1]Variance Analysis'!A29 -> Location 2 | B13: ='[1]Variance Analysis'!B29 -> Position B | C13: ='[1]Variance Analysis'!C29 -> 1314928.6 | D13: ='[1]Variance Analysis'!E29 -> 1507894.1 | E13: ='[1]Variance Analysis'!G29 -> -192965.41 | F13: ='[1]Variance Analysis'!J29 -> -65.99
A14: ='[1]Variance Analysis'!A80 -> Location 4 | B14: ='[1]Variance Analysis'!B80 -> Position A | C14: ='[1]Variance Analysis'!C80 -> 1560596.1 | D14: ='[1]Variance Analysis'!E80 -> 1735596.1 | E14: ='[1]Variance Analysis'!G80 -> -175000 | F14: ='[1]Variance Analysis'!J80 -> -60
A15: ='[1]Variance Analysis'!A54 -> Location 3 | B15: ='[1]Variance Analysis'!B54 -> Position A | C15: ='[1]Variance Analysis'!C54 -> 889662.46 | D15: ='[1]Variance Analysis'!E54 -> 1055190.3 | E15: ='[1]Variance Analysis'!G54 -> -165527.81 | F15: ='[1]Variance Analysis'!J54 -> -53.576846
A16: ='[1]Variance Analysis'!A81 -> Location 4 | B16: ='[1]Variance Analysis'!B81 -> Position B | C16: ='[1]Variance Analysis'!C81 -> 2467569.9 | D16: ='[1]Variance Analysis'!E81 -> 2613599.1 | E16: ='[1]Variance Analysis'!G81 -> -146029.16 | F16: ='[1]Variance Analysis'!J81 -> -62.9
A17: ='[1]Variance Analysis'!A6 -> Location 1 | B17: ='[1]Variance Analysis'!B6 -> Position E | C17: ='[1]Variance Analysis'!C6 -> 116986.9 | D17: ='[1]Variance Analysis'!E6 -> 248284.51 | E17: ='[1]Variance Analysis'!G6 -> -131297.61 | F17: ='[1]Variance Analysis'!J6 -> -24.456722
A18: ='[1]Variance Analysis'!A22 -> Location 1 | B18: ='[1]Variance Analysis'!B22 -> Position U | C18: ='[1]Variance Analysis'!C22 -> 188589.42 | D18: ='[1]Variance Analysis'!E22 -> 301888.72 | E18: ='[1]Variance Analysis'!G22 -> -113299.29 | F18: ='[1]Variance Analysis'!J22 -> 1
A20: Top 8 Unfavorable (largest cost overruns vs Plan)
A21: Location | B21: Position | C21: Labor $ Current Forecast | D21: Labor $ Plan | E21: Var $ vs Plan | F21: FTE Var vs Plan
A22: ='[1]Variance Analysis'!A64 -> Location 3 | B22: ='[1]Variance Analysis'!B64 -> Position K | C22: ='[1]Variance Analysis'!C64 -> 1274717 | D22: ='[1]Variance Analysis'!E64 -> 857934.8 | E22: ='[1]Variance Analysis'!G64 -> 416782.18 | F22: ='[1]Variance Analysis'!J64 -> 124.79767
A23: ='[1]Variance Analysis'!A25 -> Location 1 | B23: ='[1]Variance Analysis'!B25 -> Position X | C23: ='[1]Variance Analysis'!C25 -> 1180430.1 | D23: ='[1]Variance Analysis'!E25 -> 891350.78 | E23: ='[1]Variance Analysis'!G25 -> 289079.32 | F23: ='[1]Variance Analysis'!J25 -> 2
A24: ='[1]Variance Analysis'!A65 -> Location 3 | B24: ='[1]Variance Analysis'!B65 -> Position L | C24: ='[1]Variance Analysis'!C65 -> 356485.13 | D24: ='[1]Variance Analysis'!E65 -> 164226.05 | E24: ='[1]Variance Analysis'!G65 -> 192259.07 | F24: ='[1]Variance Analysis'!J65 -> 42.600261
A25: ='[1]Variance Analysis'!A51 -> Location 2 | B25: ='[1]Variance Analysis'!B51 -> Position X | C25: ='[1]Variance Analysis'!C51 -> 743584.25 | D25: ='[1]Variance Analysis'!E51 -> 647008.2 | E25: ='[1]Variance Analysis'!G51 -> 96576.055 | F25: ='[1]Variance Analysis'!J51 -> 18.8
A26: ='[1]Variance Analysis'!A62 -> Location 3 | B26: ='[1]Variance Analysis'!B62 -> Position I | C26: ='[1]Variance Analysis'!C62 -> 634823.01 | D26: ='[1]Variance Analysis'!E62 -> 589056.97 | E26: ='[1]Variance Analysis'!G62 -> 45766.035 | F26: ='[1]Variance Analysis'!J62 -> -11.78
A27: ='[1]Variance Analysis'!A99 -> Location 4 | B27: ='[1]Variance Analysis'!B99 -> Position T | C27: ='[1]Variance Analysis'!C99 -> 2256338 | D27: ='[1]Variance Analysis'!E99 -> 2215244.2 | E27: ='[1]Variance Analysis'!G99 -> 41093.844 | F27: ='[1]Variance Analysis'!J99 -> 2.5703167
A28: ='[1]Variance Analysis'!A94 -> Location 4 | B28: ='[1]Variance Analysis'!B94 -> Position O | C28: ='[1]Variance Analysis'!C94 -> 314685.07 | D28: ='[1]Variance Analysis'!E94 -> 273965.4 | E28: ='[1]Variance Analysis'!G94 -> 40719.675 | F28: ='[1]Variance Analysis'!J94 -> 4.1944833
A29: ='[1]Variance Analysis'!A48 -> Location 2 | B29: ='[1]Variance Analysis'!B48 -> Position U | C29: ='[1]Variance Analysis'!C48 -> 202357.83 | D29: ='[1]Variance Analysis'!E48 -> 161886.26 | E29: ='[1]Variance Analysis'!G48 -> 40471.565 | F29: ='[1]Variance Analysis'!J48 -> 3.5

Sheet Variance Analysis
A1: Location | B1: Position | C1: Labor $ Cur.Fcst | D1: Labor $ Prior Fcst | E1: Labor $ Plan | F1: Labor $ Actual 2025 | G1: Var $ vs Plan (Budget) | H1: Var % vs Plan (Budget) | I1: Var $ vs Prior Fcst | J1: FTE Var vs Plan | K1: OT % of Salary (Cur.Fcst)
A2: ='Raw - Workforce'!A55 -> Location 3 | B2: ='Raw - Workforce'!B55 -> Position B | C2: ='Raw - Workforce'!G55+'Raw - Workforce'!K55 -> 1445020.5 | D2: ='Raw - Workforce'!H55+'Raw - Workforce'!L55 -> 1486914.3 | E2: ='Raw - Workforce'!I55+'Raw - Workforce'!M55 -> 1706992.9 | F2: ='Raw - Workforce'!J55+'Raw - Workforce'!N55 -> 1744438 | G2: =C2-E2 -> -261972.36 | H2: =IFERROR(G2/E2,0) -> -0.15347009 | I2: =C2-D2 -> -41893.785 | J2: ='Raw - Workforce'!C55-'Raw - Workforce'!E55 -> -82.074351 | K2: =IFERROR('Raw - Workforce'!K55/'Raw - Workforce'!G55,0) -> 0.17854426 | M2: currently ranked from min Var- Plan
A3: ='Raw - Workforce'!A61 -> Location 3 | B3: ='Raw - Workforce'!B61 -> Position H | C3: ='Raw - Workforce'!G61+'Raw - Workforce'!K61 -> 1252895 | D3: ='Raw - Workforce'!H61+'Raw - Workforce'!L61 -> 1274973.9 | E3: ='Raw - Workforce'!I61+'Raw - Workforce'!M61 -> 1457336.4 | F3: ='Raw - Workforce'!J61+'Raw - Workforce'!N61 -> 1449146 | G3: =C3-E3 -> -204441.42 | H3: =IFERROR(G3/E3,0) -> -0.1402843 | I3: =C3-D3 -> -22078.864 | J3: ='Raw - Workforce'!C61-'Raw - Workforce'!E61 -> -43.626628 | K3: =IFERROR('Raw - Workforce'!K61/'Raw - Workforce'!G61,0) -> 0.099223176
A4: ='Raw - Workforce'!A29 -> Location 2 | B4: ='Raw - Workforce'!B29 -> Position B | C4: ='Raw - Workforce'!G29+'Raw - Workforce'!K29 -> 1314928.6 | D4: ='Raw - Workforce'!H29+'Raw - Workforce'!L29 -> 1267658.3 | E4: ='Raw - Workforce'!I29+'Raw - Workforce'!M29 -> 1507894.1 | F4: ='Raw - Workforce'!J29+'Raw - Workforce'!N29 -> 1286692.2 | G4: =C4-E4 -> -192965.41 | H4: =IFERROR(G4/E4,0) -> -0.12797014 | I4: =C4-D4 -> 47270.339 | J4: ='Raw - Workforce'!C29-'Raw - Workforce'!E29 -> -65.99 | K4: =IFERROR('Raw - Workforce'!K29/'Raw - Workforce'!G29,0) -> 0.071724466 | M4: then reversed from greatest to least to observe favorable and unfavorable outcomes
A5: ='Raw - Workforce'!A80 -> Location 4 | B5: ='Raw - Workforce'!B80 -> Position A | C5: ='Raw - Workforce'!G80+'Raw - Workforce'!K80 -> 1560596.1 | D5: ='Raw - Workforce'!H80+'Raw - Workforce'!L80 -> 1688562.3 | E5: ='Raw - Workforce'!I80+'Raw - Workforce'!M80 -> 1735596.1 | F5: ='Raw - Workforce'!J80+'Raw - Workforce'!N80 -> 1651815.2 | G5: =C5-E5 -> -175000 | H5: =IFERROR(G5/E5,0) -> -0.10082991 | I5: =C5-D5 -> -127966.24 | J5: ='Raw - Workforce'!C80-'Raw - Workforce'!E80 -> -60 | K5: =IFERROR('Raw - Workforce'!K80/'Raw - Workforce'!G80,0) -> 0.11844628
A6: ='Raw - Workforce'!A54 -> Location 3 | B6: ='Raw - Workforce'!B54 -> Position A | C6: ='Raw - Workforce'!G54+'Raw - Workforce'!K54 -> 889662.46 | D6: ='Raw - Workforce'!H54+'Raw - Workforce'!L54 -> 855580.97 | E6: ='Raw - Workforce'!I54+'Raw - Workforce'!M54 -> 1055190.3 | F6: ='Raw - Workforce'!J54+'Raw - Workforce'!N54 -> 1017975.4 | G6: =C6-E6 -> -165527.81 | H6: =IFERROR(G6/E6,0) -> -0.15687011 | I6: =C6-D6 -> 34081.488 | J6: ='Raw - Workforce'!C54-'Raw - Workforce'!E54 -> -53.576846 | K6: =IFERROR('Raw - Workforce'!K54/'Raw - Workforce'!G54,0) -> 0.099182289
A7: ='Raw - Workforce'!A81 -> Location 4 | B7: ='Raw - Workforce'!B81 -> Position B | C7: ='Raw - Workforce'!G81+'Raw - Workforce'!K81 -> 2467569.9 | D7: ='Raw - Workforce'!H81+'Raw - Workforce'!L81 -> 2359061.8 | E7: ='Raw - Workforce'!I81+'Raw - Workforce'!M81 -> 2613599.1 | F7: ='Raw - Workforce'!J81+'Raw - Workforce'!N81 -> 2482689.4 | G7: =C7-E7 -> -146029.16 | H7: =IFERROR(G7/E7,0) -> -0.055872823 | I7: =C7-D7 -> 108508.16 | J7: ='Raw - Workforce'!C81-'Raw - Workforce'!E81 -> -62.9 | K7: =IFERROR('Raw - Workforce'!K81/'Raw - Workforce'!G81,0) -> 0.14475791
A8: ='Raw - Workforce'!A6 -> Location 1 | B8: ='Raw - Workforce'!B6 -> Position E | C8: ='Raw - Workforce'!G6+'Raw - Workforce'!K6 -> 116986.9 | D8: ='Raw - Workforce'!H6+'Raw - Workforce'!L6 -> 185360.55 | E8: ='Raw - Workforce'!I6+'Raw - Workforce'!M6 -> 248284.51 | F8: ='Raw - Workforce'!J6+'Raw - Workforce'!N6 -> 215242.21 | G8: =C8-E8 -> -131297.61 | H8: =IFERROR(G8/E8,0) -> -0.52881916 | I8: =C8-D8 -> -68373.641 | J8: ='Raw - Workforce'!C6-'Raw - Workforce'!E6 -> -24.456722 | K8: =IFERROR('Raw - Workforce'!K6/'Raw - Workforce'!G6,0) -> 0.24345613
A9: ='Raw - Workforce'!A22 -> Location 1 | B9: ='Raw - Workforce'!B22 -> Position U | C9: ='Raw - Workforce'!G22+'Raw - Workforce'!K22 -> 188589.42 | D9: ='Raw - Workforce'!H22+'Raw - Workforce'!L22 -> 188589.42 | E9: ='Raw - Workforce'!I22+'Raw - Workforce'!M22 -> 301888.72 | F9: ='Raw - Workforce'!J22+'Raw - Workforce'!N22 -> 287026.73 | G9: =C9-E9 -> -113299.29 | H9: =IFERROR(G9/E9,0) -> -0.37530151 | I9: =C9-D9 -> 0 | J9: ='Raw - Workforce'!C22-'Raw - Workforce'!E22 -> 1 | K9: =IFERROR('Raw - Workforce'!K22/'Raw - Workforce'!G22,0) -> -0.0016195801
A10: ='Raw - Workforce'!A13 -> Location 1 | B10: ='Raw - Workforce'!B13 -> Position L | C10: ='Raw - Workforce'!G13+'Raw - Workforce'!K13 -> 660012.41 | D10: ='Raw - Workforce'!H13+'Raw - Workforce'!L13 -> 660012.41 | E10: ='Raw - Workforce'!I13+'Raw - Workforce'!M13 -> 756530.2 | F10: ='Raw - Workforce'!J13+'Raw - Workforce'!N13 -> 690487.45 | G10: =C10-E10 -> -96517.79 | H10: =IFERROR(G10/E10,0) -> -0.12757956 | I10: =C10-D10 -> 0 | J10: ='Raw - Workforce'!C13-'Raw - Workforce'!E13 -> -32.418709 | K10: =IFERROR('Raw - Workforce'!K13/'Raw - Workforce'!G13,0) -> 0.15112895
A11: ='Raw - Workforce'!A12 -> Location 1 | B11: ='Raw - Workforce'!B12 -> Position K | C11: ='Raw - Workforce'!G12+'Raw - Workforce'!K12 -> 654204.24 | D11: ='Raw - Workforce'!H12+'Raw - Workforce'!L12 -> 654204.24 | E11: ='Raw - Workforce'!I12+'Raw - Workforce'!M12 -> 747824.4 | F11: ='Raw - Workforce'!J12+'Raw - Workforce'!N12 -> 658390.69 | G11: =C11-E11 -> -93620.153 | H11: =IFERROR(G11/E11,0) -> -0.12519002 | I11: =C11-D11 -> 0 | J11: ='Raw - Workforce'!C12-'Raw - Workforce'!E12 -> -16.59 | K11: =IFERROR('Raw - Workforce'!K12/'Raw - Workforce'!G12,0) -> 0.15112895
A12: ='Raw - Workforce'!A69 -> Location 3 | B12: ='Raw - Workforce'!B69 -> Position P | C12: ='Raw - Workforce'!G69+'Raw - Workforce'!K69 -> 515660.66 | D12: ='Raw - Workforce'!H69+'Raw - Workforce'!L69 -> 522817.51 | E12: ='Raw - Workforce'!I69+'Raw - Workforce'!M69 -> 600654.21 | F12: ='Raw - Workforce'!J69+'Raw - Workforce'!N69 -> 508169.82 | G12: =C12-E12 -> -84993.544 | H12: =IFERROR(G12/E12,0) -> -0.14150162 | I12: =C12-D12 -> -7156.8476 | J12: ='Raw - Workforce'!C69-'Raw - Workforce'!E69 -> -7.5 | K12: =IFERROR('Raw - Workforce'!K69/'Raw - Workforce'!G69,0) -> 0.10206544
A13: ='Raw - Workforce'!A77 -> Location 3 | B13: ='Raw - Workforce'!B77 -> Position X | C13: ='Raw - Workforce'!G77+'Raw - Workforce'!K77 -> 765628.09 | D13: ='Raw - Workforce'!H77+'Raw - Workforce'!L77 -> 760506.83 | E13: ='Raw - Workforce'!I77+'Raw - Workforce'!M77 -> 826019.44 | F13: ='Raw - Workforce'!J77+'Raw - Workforce'!N77 -> 777317.01 | G13: =C13-E13 -> -60391.352 | H13: =IFERROR(G13/E13,0) -> -0.073111296 | I13: =C13-D13 -> 5121.2581 | J13: ='Raw - Workforce'!C77-'Raw - Workforce'!E77 -> -13.88 | K13: =IFERROR('Raw - Workforce'!K77/'Raw - Workforce'!G77,0) -> 0
A14: ='Raw - Workforce'!A28 -> Location 2 | B14: ='Raw - Workforce'!B28 -> Position A | C14: ='Raw - Workforce'!G28+'Raw - Workforce'!K28 -> 1090197 | D14: ='Raw - Workforce'!H28+'Raw - Workforce'!L28 -> 1032113 | E14: ='Raw - Workforce'!I28+'Raw - Workforce'!M28 -> 1149261.3 | F14: ='Raw - Workforce'!J28+'Raw - Workforce'!N28 -> 1056739.5 | G14: =C14-E14 -> -59064.326 | H14: =IFERROR(G14/E14,0) -> -0.051393295 | I14: =C14-D14 -> 58083.98 | J14: ='Raw - Workforce'!C28-'Raw - Workforce'!E28 -> -25.56 | K14: =IFERROR('Raw - Workforce'!K28/'Raw - Workforce'!G28,0) -> 0.10278399
A15: ='Raw - Workforce'!A38 -> Location 2 | B15: ='Raw - Workforce'!B38 -> Position K | C15: ='Raw - Workforce'!G38+'Raw - Workforce'!K38 -> 443064.7 | D15: ='Raw - Workforce'!H38+'Raw - Workforce'!L38 -> 443064.7 | E15: ='Raw - Workforce'!I38+'Raw - Workforce'!M38 -> 493294.42 | F15: ='Raw - Workforce'!J38+'Raw - Workforce'!N38 -> 488091.83 | G15: =C15-E15 -> -50229.72 | H15: =IFERROR(G15/E15,0) -> -0.10182503 | I15: =C15-D15 -> 0 | J15: ='Raw - Workforce'!C38-'Raw - Workforce'!E38 -> -31.46 | K15: =IFERROR('Raw - Workforce'!K38/'Raw - Workforce'!G38,0) -> 0.047969925
A16: ='Raw - Workforce'!A95 -> Location 4 | B16: ='Raw - Workforce'!B95 -> Position P | C16: ='Raw - Workforce'!G95+'Raw - Workforce'!K95 -> 720860.12 | D16: ='Raw - Workforce'!H95+'Raw - Workforce'!L95 -> 730860.12 | E16: ='Raw - Workforce'!I95+'Raw - Workforce'!M95 -> 765042.52 | F16: ='Raw - Workforce'!J95+'Raw - Workforce'!N95 -> 776666.77 | G16: =C16-E16 -> -44182.402 | H16: =IFERROR(G16/E16,0) -> -0.057751564 | I16: =C16-D16 -> -10000 | J16: ='Raw - Workforce'!C95-'Raw - Workforce'!E95 -> -8.2583333 | K16: =IFERROR('Raw - Workforce'!K95/'Raw - Workforce'!G95,0) -> 0.079624755
A17: ='Raw - Workforce'!A39 -> Location 2 | B17: ='Raw - Workforce'!B39 -> Position L | C17: ='Raw - Workforce'!G39+'Raw - Workforce'!K39 -> 336023.19 | D17: ='Raw - Workforce'!H39+'Raw - Workforce'!L39 -> 337174.23 | E17: ='Raw - Workforce'!I39+'Raw - Workforce'!M39 -> 380200.14 | F17: ='Raw - Workforce'!J39+'Raw - Workforce'!N39 -> 332506.43 | G17: =C17-E17 -> -44176.946 | H17: =IFERROR(G17/E17,0) -> -0.11619392 | I17: =C17-D17 -> -1151.0408 | J17: ='Raw - Workforce'!C39-'Raw - Workforce'!E39 -> -19.19 | K17: =IFERROR('Raw - Workforce'!K39/'Raw - Workforce'!G39,0) -> 0.056109794
A18: ='Raw - Workforce'!A31 -> Location 2 | B18: ='Raw - Workforce'!B31 -> Position D | C18: ='Raw - Workforce'!G31+'Raw - Workforce'!K31 -> 84744.859 | D18: ='Raw - Workforce'!H31+'Raw - Workforce'!L31 -> 79136.859 | E18: ='Raw - Workforce'!I31+'Raw - Workforce'!M31 -> 121165.07 | F18: ='Raw - Workforce'!J31+'Raw - Workforce'!N31 -> 118985.56 | G18: =C18-E18 -> -36420.212 | H18: =IFERROR(G18/E18,0) -> -0.30058343 | I18: =C18-D18 -> 5608 | J18: ='Raw - Workforce'!C31-'Raw - Workforce'!E31 -> -16.27 | K18: =IFERROR('Raw - Workforce'!K31/'Raw - Workforce'!G31,0) -> 0.099012566
A19: ='Raw - Workforce'!A100 -> Location 4 | B19: ='Raw - Workforce'!B100 -> Position U | C19: ='Raw - Workforce'!G100+'Raw - Workforce'!K100 -> 337062.55 | D19: ='Raw - Workforce'!H100+'Raw - Workforce'!L100 -> 337760.55 | E19: ='Raw - Workforce'!I100+'Raw - Workforce'!M100 -> 369062.55 | F19: ='Raw - Workforce'!J100+'Raw - Workforce'!N100 -> 361260.55 | G19: =C19-E19 -> -32000 | H19: =IFERROR(G19/E19,0) -> -0.086706169 | I19: =C19-D19 -> -698 | J19: ='Raw - Workforce'!C100-'Raw - Workforce'!E100 -> 0.6 | K19: =IFERROR('Raw - Workforce'!K100/'Raw - Workforce'!G100,0) -> 0
A20: ='Raw - Workforce'!A24 -> Location 1 | B20: ='Raw - Workforce'!B24 -> Position W | C20: ='Raw - Workforce'!G24+'Raw - Workforce'!K24 -> -3.6379788e-12 | D20: ='Raw - Workforce'!H24+'Raw - Workforce'!L24 -> -3.6379788e-12 | E20: ='Raw - Workforce'!I24+'Raw - Workforce'!M24 -> 31615.827 | F20: ='Raw - Workforce'!J24+'Raw - Workforce'!N24 -> 88800.08 | G20: =C20-E20 -> -31615.827 | H20: =IFERROR(G20/E20,0) -> -1 | I20: =C20-D20 -> 0 | J20: ='Raw - Workforce'!C24-'Raw - Workforce'!E24 -> -0.5 | K20: =IFERROR('Raw - Workforce'!K24/'Raw - Workforce'!G24,0) -> 0
A21: ='Raw - Workforce'!A73 -> Location 3 | B21: ='Raw - Workforce'!B73 -> Position T | C21: ='Raw - Workforce'!G73+'Raw - Workforce'!K73 -> 1681988.2 | D21: ='Raw - Workforce'!H73+'Raw - Workforce'!L73 -> 1717285.7 | E21: ='Raw - Workforce'!I73+'Raw - Workforce'!M73 -> 1712862.5 | F21: ='Raw - Workforce'!J73+'Raw - Workforce'!N73 -> 1646223 | G21: =C21-E21 -> -30874.383 | H21: =IFERROR(G21/E21,0) -> -0.018025021 | I21: =C21-D21 -> -35297.55 | J21: ='Raw - Workforce'!C73-'Raw - Workforce'!E73 -> 4.4330119 | K21: =IFERROR('Raw - Workforce'!K73/'Raw - Workforce'!G73,0) -> 0.080812796
A22: ='Raw - Workforce'!A16 -> Location 1 | B22: ='Raw - Workforce'!B16 -> Position O | C22: ='Raw - Workforce'!G16+'Raw - Workforce'!K16 -> 157550.22 | D22: ='Raw - Workforce'!H16+'Raw - Workforce'!L16 -> 157550.22 | E22: ='Raw - Workforce'!I16+'Raw - Workforce'!M16 -> 187654.9 | F22: ='Raw - Workforce'!J16+'Raw - Workforce'!N16 -> 179832.32 | G22: =C22-E22 -> -30104.681 | H22: =IFERROR(G22/E22,0) -> -0.16042576 | I22: =C22-D22 -> 0 | J22: ='Raw - Workforce'!C16-'Raw - Workforce'!E16 -> -10.713423 | K22: =IFERROR('Raw - Workforce'!K16/'Raw - Workforce'!G16,0) -> 0.22645103
A23: ='Raw - Workforce'!A57 -> Location 3 | B23: ='Raw - Workforce'!B57 -> Position D | C23: ='Raw - Workforce'!G57+'Raw - Workforce'!K57 -> 0 | D23: ='Raw - Workforce'!H57+'Raw - Workforce'!L57 -> 0 | E23: ='Raw - Workforce'!I57+'Raw - Workforce'!M57 -> 30047.743 | F23: ='Raw - Workforce'!J57+'Raw - Workforce'!N57 -> 10975.15 | G23: =C23-E23 -> -30047.743 | H23: =IFERROR(G23/E23,0) -> -1 | I23: =C23-D23 -> 0 | J23: ='Raw - Workforce'!C57-'Raw - Workforce'!E57 -> -8.5 | K23: =IFERROR('Raw - Workforce'!K57/'Raw - Workforce'!G57,0) -> 0
A24: ='Raw - Workforce'!A52 -> Location 2 | B24: ='Raw - Workforce'!B52 -> Position Y | C24: ='Raw - Workforce'!G52+'Raw - Workforce'!K52 -> 154633.49 | D24: ='Raw - Workforce'!H52+'Raw - Workforce'!L52 -> 154633.49 | E24: ='Raw - Workforce'!I52+'Raw - Workforce'!M52 -> 183627.27 | F24: ='Raw - Workforce'!J52+'Raw - Workforce'!N52 -> 0 | G24: =C24-E24 -> -28993.78 | H24: =IFERROR(G24/E24,0) -> -0.15789474 | I24: =C24-D24 -> 0 | J24: ='Raw - Workforce'!C52-'Raw - Workforce'!E52 -> -3 | K24: =IFERROR('Raw - Workforce'!K52/'Raw - Workforce'!G52,0) -> 0
A25: ='Raw - Workforce'!A3 -> Location 1 | B25: ='Raw - Workforce'!B3 -> Position B | C25: ='Raw - Workforce'!G3+'Raw - Workforce'!K3 -> 1650151 | D25: ='Raw - Workforce'!H3+'Raw - Workforce'!L3 -> 1673096.8 | E25: ='Raw - Workforce'!I3+'Raw - Workforce'!M3 -> 1678200.4 | F25: ='Raw - Workforce'!J3+'Raw - Workforce'!N3 -> 1469307.8 | G25: =C25-E25 -> -28049.437 | H25: =IFERROR(G25/E25,0) -> -0.016713997 | I25: =C25-D25 -> -22945.85 | J25: ='Raw - Workforce'!C3-'Raw - Workforce'!E3 -> -44.673278 | K25: =IFERROR('Raw - Workforce'!K3/'Raw - Workforce'!G3,0) -> 0.21106855
A26: ='Raw - Workforce'!A33 -> Location 2 | B26: ='Raw - Workforce'!B33 -> Position F | C26: ='Raw - Workforce'!G33+'Raw - Workforce'!K33 -> 44224.196 | D26: ='Raw - Workforce'!H33+'Raw - Workforce'!L33 -> 44224.196 | E26: ='Raw - Workforce'!I33+'Raw - Workforce'!M33 -> 70518.748 | F26: ='Raw - Workforce'!J33+'Raw - Workforce'!N33 -> 66201.63 | G26: =C26-E26 -> -26294.553 | H26: =IFERROR(G26/E26,0) -> -0.37287322 | I26: =C26-D26 -> 0 | J26: ='Raw - Workforce'!C33-'Raw - Workforce'!E33 -> -10.86 | K26: =IFERROR('Raw - Workforce'!K33/'Raw - Workforce'!G33,0) -> 0.11034535
A27: ='Raw - Workforce'!A23 -> Location 1 | B27: ='Raw - Workforce'!B23 -> Position V | C27: ='Raw - Workforce'!G23+'Raw - Workforce'!K23 -> 160650.25 | D27: ='Raw - Workforce'!H23+'Raw - Workforce'!L23 -> 160650.25 | E27: ='Raw - Workforce'!I23+'Raw - Workforce'!M23 -> 186792.57 | F27: ='Raw - Workforce'!J23+'Raw - Workforce'!N23 -> 149000.3 | G27: =C27-E27 -> -26142.315 | H27: =IFERROR(G27/E27,0) -> -0.13995372 | I27: =C27-D27 -> 0 | J27: ='Raw - Workforce'!C23-'Raw - Workforce'!E23 -> 0 | K27: =IFERROR('Raw - Workforce'!K23/'Raw - Workforce'!G23,0) -> -0.0016195801
A28: ='Raw - Workforce'!A2 -> Location 1 | B28: ='Raw - Workforce'!B2 -> Position A | C28: ='Raw - Workforce'!G2+'Raw - Workforce'!K2 -> 1314625.2 | D28: ='Raw - Workforce'!H2+'Raw - Workforce'!L2 -> 1318388.6 | E28: ='Raw - Workforce'!I2+'Raw - Workforce'!M2 -> 1339965.4 | F28: ='Raw - Workforce'!J2+'Raw - Workforce'!N2 -> 1283926.9 | G28: =C28-E28 -> -25340.162 | H28: =IFERROR(G28/E28,0) -> -0.018911057 | I28: =C28-D28 -> -3763.4062 | J28: ='Raw - Workforce'!C2-'Raw - Workforce'!E2 -> -17.286202 | K28: =IFERROR('Raw - Workforce'!K2/'Raw - Workforce'!G2,0) -> 0.18321702
A29: ='Raw - Workforce'!A88 -> Location 4 | B29: ='Raw - Workforce'!B88 -> Position I | C29: ='Raw - Workforce'!G88+'Raw - Workforce'!K88 -> 351680.68 | D29: ='Raw - Workforce'!H88+'Raw - Workforce'!L88 -> 356280.68 | E29: ='Raw - Workforce'!I88+'Raw - Workforce'!M88 -> 375851.68 | F29: ='Raw - Workforce'!J88+'Raw - Workforce'!N88 -> 359971.02 | G29: =C29-E29 -> -24171 | H29: =IFERROR(G29/E29,0) -> -0.064309943 | I29: =C29-D29 -> -4600 | J29: ='Raw - Workforce'!C88-'Raw - Workforce'!E88 -> -9.5 | K29: =IFERROR('Raw - Workforce'!K88/'Raw - Workforce'!G88,0) -> 0.097540753
A30: ='Raw - Workforce'!A50 -> Location 2 | B30: ='Raw - Workforce'!B50 -> Position W | C30: ='Raw - Workforce'!G50+'Raw - Workforce'!K50 -> 13841.685 | D30: ='Raw - Workforce'!H50+'Raw - Workforce'!L50 -> 941.68467 | E30: ='Raw - Workforce'!I50+'Raw - Workforce'!M50 -> 35400.47 | F30: ='Raw - Workforce'!J50+'Raw - Workforce'!N50 -> 48138.02 | G30: =C30-E30 -> -21558.785 | H30: =IFERROR(G30/E30,0) -> -0.60899715 | I30: =C30-D30 -> 12900 | J30: ='Raw - Workforce'!C50-'Raw - Workforce'!E50 -> -6.34 | K30: =IFERROR('Raw - Workforce'!K50/'Raw - Workforce'!G50,0) -> 0.072998812
A31: ='Raw - Workforce'!A7 -> Location 1 | B31: ='Raw - Workforce'!B7 -> Position F | C31: ='Raw - Workforce'!G7+'Raw - Workforce'!K7 -> 87904.33 | D31: ='Raw - Workforce'!H7+'Raw - Workforce'!L7 -> 90845.556 | E31: ='Raw - Workforce'!I7+'Raw - Workforce'!M7 -> 107694.18 | F31: ='Raw - Workforce'!J7+'Raw - Workforce'!N7 -> 55439.6 | G31: =C31-E31 -> -19789.85 | H31: =IFERROR(G31/E31,0) -> -0.1837597 | I31: =C31-D31 -> -2941.2262 | J31: ='Raw - Workforce'!C7-'Raw - Workforce'!E7 -> -3.9 | K31: =IFERROR('Raw - Workforce'!K7/'Raw - Workforce'!G7,0) -> 0.1463995
A32: ='Raw - Workforce'!A43 -> Location 2 | B32: ='Raw - Workforce'!B43 -> Position P | C32: ='Raw - Workforce'!G43+'Raw - Workforce'!K43 -> 407779.44 | D32: ='Raw - Workforce'!H43+'Raw - Workforce'!L43 -> 411869.41 | E32: ='Raw - Workforce'!I43+'Raw - Workforce'!M43 -> 424795.8 | F32: ='Raw - Workforce'!J43+'Raw - Workforce'!N43 -> 430909.74 | G32: =C32-E32 -> -17016.357 | H32: =IFERROR(G32/E32,0) -> -0.040057733 | I32: =C32-D32 -> -4089.971 | J32: ='Raw - Workforce'!C43-'Raw - Workforce'!E43 -> -8.0315064 | K32: =IFERROR('Raw - Workforce'!K43/'Raw - Workforce'!G43,0) -> 0.12912834
A33: ='Raw - Workforce'!A87 -> Location 4 | B33: ='Raw - Workforce'!B87 -> Position H | C33: ='Raw - Workforce'!G87+'Raw - Workforce'!K87 -> 1119106.8 | D33: ='Raw - Workforce'!H87+'Raw - Workforce'!L87 -> 1139106.8 | E33: ='Raw - Workforce'!I87+'Raw - Workforce'!M87 -> 1136024.8 | F33: ='Raw - Workforce'!J87+'Raw - Workforce'!N87 -> 987809.41 | G33: =C33-E33 -> -16918 | H33: =IFERROR(G33/E33,0) -> -0.014892281 | I33: =C33-D33 -> -20000 | J33: ='Raw - Workforce'!C87-'Raw - Workforce'!E87 -> -11.6 | K33: =IFERROR('Raw - Workforce'!K87/'Raw - Workforce'!G87,0) -> 0.070535698
A34: ='Raw - Workforce'!A97 -> Location 4 | B34: ='Raw - Workforce'!B97 -> Position R | C34: ='Raw - Workforce'!G97+'Raw - Workforce'!K97 -> 262229.54 | D34: ='Raw - Workforce'!H97+'Raw - Workforce'!L97 -> 269229.54 | E34: ='Raw - Workforce'!I97+'Raw - Workforce'!M97 -> 273446.69 | F34: ='Raw - Workforce'!J97+'Raw - Workforce'!N97 -> 182320.05 | G34: =C34-E34 -> -11217.145 | H34: =IFERROR(G34/E34,0) -> -0.041021325 | I34: =C34-D34 -> -7000 | J34: ='Raw - Workforce'!C97-'Raw - Workforce'!E97 -> -4.01 | K34: =IFERROR('Raw - Workforce'!K97/'Raw - Workforce'!G97,0) -> 0.048245222
A35: ='Raw - Workforce'!A103 -> Location 4 | B35: ='Raw - Workforce'!B103 -> Position X | C35: ='Raw - Workforce'!G103+'Raw - Workforce'!K103 -> 1136975.6 | D35: ='Raw - Workforce'!H103+'Raw - Workforce'!L103 -> 1136975.6 | E35: ='Raw - Workforce'!I103+'Raw - Workforce'!M103 -> 1147522.6 | F35: ='Raw - Workforce'!J103+'Raw - Workforce'!N103 -> 936301.12 | G35: =C35-E35 -> -10547 | H35: =IFERROR(G35/E35,0) -> -0.009191104 | I35: =C35-D35 -> 0 | J35: ='Raw - Workforce'!C103-'Raw - Workforce'!E103 -> -2.1 | K35: =IFERROR('Raw - Workforce'!K103/'Raw - Workforce'!G103,0) -> 0
A36: ='Raw - Workforce'!A10 -> Location 1 | B36: ='Raw - Workforce'!B10 -> Position I | C36: ='Raw - Workforce'!G10+'Raw - Workforce'!K10 -> 334192.45 | D36: ='Raw - Workforce'!H10+'Raw - Workforce'!L10 -> 334192.45 | E36: ='Raw - Workforce'!I10+'Raw - Workforce'!M10 -> 343557.18 | F36: ='Raw - Workforce'!J10+'Raw - Workforce'!N10 -> 333783.6 | G36: =C36-E36 -> -9364.7229 | H36: =IFERROR(G36/E36,0) -> -0.02725812 | I36: =C36-D36 -> 0 | J36: ='Raw - Workforce'!C10-'Raw - Workforce'!E10 -> 2.25 | K36: =IFERROR('Raw - Workforce'!K10/'Raw - Workforce'!G10,0) -> 0.15324713
A37: ='Raw - Workforce'!A21 -> Location 1 | B37: ='Raw - Workforce'!B21 -> Position T | C37: ='Raw - Workforce'!G21+'Raw - Workforce'!K21 -> 1201881.1 | D37: ='Raw - Workforce'!H21+'Raw - Workforce'!L21 -> 1201881.1 | E37: ='Raw - Workforce'!I21+'Raw - Workforce'!M21 -> 1210884.5 | F37: ='Raw - Workforce'!J21+'Raw - Workforce'!N21 -> 1213868.9 | G37: =C37-E37 -> -9003.4138 | H37: =IFERROR(G37/E37,0) -> -0.0074354029 | I37: =C37-D37 -> 0 | J37: ='Raw - Workforce'!C21-'Raw - Workforce'!E21 -> -9.8067154 | K37: =IFERROR('Raw - Workforce'!K21/'Raw - Workforce'!G21,0) -> 0.10111883
A38: ='Raw - Workforce'!A101 -> Location 4 | B38: ='Raw - Workforce'!B101 -> Position V | C38: ='Raw - Workforce'!G101+'Raw - Workforce'!K101 -> 196135.16 | D38: ='Raw - Workforce'!H101+'Raw - Workforce'!L101 -> 196135.16 | E38: ='Raw - Workforce'!I101+'Raw - Workforce'!M101 -> 203622.16 | F38: ='Raw - Workforce'!J101+'Raw - Workforce'!N101 -> 199587.02 | G38: =C38-E38 -> -7487 | H38: =IFERROR(G38/E38,0) -> -0.036769083 | I38: =C38-D38 -> 0 | J38: ='Raw - Workforce'!C101-'Raw - Workforce'!E101 -> 0 | K38: =IFERROR('Raw - Workforce'!K101/'Raw - Workforce'!G101,0) -> 0
A39: ='Raw - Workforce'!A85 -> Location 4 | B39: ='Raw - Workforce'!B85 -> Position F | C39: ='Raw - Workforce'!G85+'Raw - Workforce'!K85 -> 196337.37 | D39: ='Raw - Workforce'!H85+'Raw - Workforce'!L85 -> 188708.32 | E39: ='Raw - Workforce'!I85+'Raw - Workforce'!M85 -> 203337.37 | F39: ='Raw - Workforce'!J85+'Raw - Workforce'!N85 -> 244749.3 | G39: =C39-E39 -> -7000 | H39: =IFERROR(G39/E39,0) -> -0.034425546 | I39: =C39-D39 -> 7629.0557 | J39: ='Raw - Workforce'!C85-'Raw - Workforce'!E85 -> -1.7 | K39: =IFERROR('Raw - Workforce'!K85/'Raw - Workforce'!G85,0) -> 0.1175757
A40: ='Raw - Workforce'!A84 -> Location 4 | B40: ='Raw - Workforce'!B84 -> Position E | C40: ='Raw - Workforce'!G84+'Raw - Workforce'!K84 -> 330340.16 | D40: ='Raw - Workforce'!H84+'Raw - Workforce'!L84 -> 330340.16 | E40: ='Raw - Workforce'!I84+'Raw - Workforce'!M84 -> 336857.16 | F40: ='Raw - Workforce'!J84+'Raw - Workforce'!N84 -> 371830.14 | G40: =C40-E40 -> -6517 | H40: =IFERROR(G40/E40,0) -> -0.019346479 | I40: =C40-D40 -> 0 | J40: ='Raw - Workforce'!C84-'Raw - Workforce'!E84 -> -4.6 | K40: =IFERROR('Raw - Workforce'!K84/'Raw - Workforce'!G84,0) -> 0.066262065
...

Sheet Raw - Workforce
A1: Location | B1: Position | C1: FTE Cur.Fcst | D1: FTE Prior Fcst | E1: FTE Plan | F1: FTE Actual 2025 | G1: Salary $ Cur.Fcst | H1: Salary $ Prior Fcst | I1: Salary $ Plan | J1: Salary $ Actual 2025 | K1: OT $ Cur.Fcst | L1: OT $ Prior Fcst | M1: OT $ Plan | N1: OT $ Actual 2025
A2: Location 1 | B2: Position A | C2: 332.54194 | D2: 332.87073 | E2: 349.82814 | F2: 345.88 | G2: 1111060.1 | H2: 1114823.5 | I2: 1100596.5 | J2: 1067045.8 | K2: 203565.12 | L2: 203565.12 | M2: 239368.89 | N2: 216881.04
A3: Location 1 | B3: Position B | C3: 408.85126 | D3: 431.64203 | E3: 453.52454 | F3: 410.64 | G3: 1362557.9 | H3: 1385503.7 | I3: 1301697.3 | J3: 1126091.5 | K3: 287593.12 | L3: 287593.12 | M3: 376503.1 | N3: 343216.31
A4: Location 1 | B4: Position C | C4: 0 | D4: 0 | E4: 0 | F4: 0 | G4: 0 | H4: 0 | I4: 0 | J4: 0 | K4: 0 | L4: 0 | M4: 0 | N4: 0
A5: Location 1 | B5: Position D | C5: 15.745291 | D5: 15.745291 | E5: 17.106021 | F5: 17.38 | G5: 51777.991 | H5: 51777.991 | I5: 55730.414 | J5: 58083.13 | K5: 7300.2504 | L5: 7300.2504 | M5: 7255.5678 | N5: 8154.34
A6: Location 1 | B6: Position E | C6: 48.037148 | D6: 49.401535 | E6: 72.49387 | F6: 63.51 | G6: 94082.052 | H6: 162455.69 | I6: 203710.48 | J6: 176456.01 | K6: 22904.852 | L6: 22904.852 | M6: 44574.03 | N6: 38786.2
A7: Location 1 | B7: Position F | C7: 21.6 | D7: 24.211786 | E7: 25.5 | F7: 15.65 | G7: 76678.618 | H7: 79619.845 | I7: 84150.916 | J7: 37219.6 | K7: 11225.712 | L7: 11225.712 | M7: 23543.264 | N7: 18220
A8: Location 1 | B8: Position G | C8: 13.998619 | D8: 13.998619 | E8: 14.5 | F8: 16.11 | G8: 46034.105 | H8: 46034.105 | I8: 46759.045 | J8: 47619.3 | K8: 6490.412 | L8: 6490.412 | M8: 6170.363 | N8: 6509.13
A9: Location 1 | B9: Position H | C9: 190.79341 | D9: 185.42668 | E9: 180.01858 | F9: 168.89 | G9: 625673.71 | H9: 609770.93 | I9: 563240.4 | J9: 516731.03 | K9: 85972.445 | L9: 85972.445 | M9: 121191.63 | N9: 112868.14
A10: Location 1 | B10: Position I | C10: 88 | D10: 88 | E10: 85.75 | F10: 84.77 | G10: 289783.9 | H10: 289783.9 | I10: 294434.76 | J10: 282706 | K10: 44408.551 | L10: 44408.551 | M10: 49122.415 | N10: 51077.6
A11: Location 1 | B11: Position J | C11: 0 | D11: 0 | E11: 1 | F11: 1.35 | G11: 0 | H11: 0 | I11: 3443.0593 | J11: 3298.13 | K11: 0 | L11: 0 | M11: 203.00513 | N11: 194.46
A12: Location 1 | B12: Position K | C12: 207.91 | D12: 207.91 | E12: 224.5 | F12: 210.29 | G12: 568315.34 | H12: 568315.34 | I12: 664572.16 | J12: 586412.14 | K12: 85888.899 | L12: 85888.899 | M12: 83252.236 | N12: 71978.55
A13: Location 1 | B13: Position L | C13: 209.58129 | D13: 209.75587 | E13: 242 | F13: 214.97 | G13: 573360.98 | H13: 573360.98 | I13: 616633.57 | J13: 531760.52 | K13: 86651.44 | L13: 86651.44 | M13: 139896.64 | N13: 158726.93
... A105: Location 4 | B105: Position Z | C105: 0 | D105: 0 | E105: 0 | F105: 0 | G105: 0 | H105: 0 | I105: 0 | J105: 0 | K105: 0 | L105: 0 | M105: 0 | N105: 0
A107: Source: Workforce_Analysis.xlsx, "Workforce Data" tab, rows 5-111 (as provided by user).

Sheet Raw - Transactions
A1: Location | B1: Rental Transactions 2026 Actual (YTD) | C1: Rental Transactions 2026 Prior Forecast | D1: Rental Transactions 2026 Plan | E1: Rental Transactions 2025 Actual
A2: Location 1 | B2: 366934 | C2: 425982.47 | D2: 425982.47 | E2: 402999
A3: Location 2 | B3: 550595 | C3: 599083.3 | D3: 599083.3 | E3: 593382
A4: Location 3 | B4: 539902 | C4: 625480.95 | D4: 625480.95 | E4: 602273
A5: Location 4 | B5: 566690 | C5: 629076.38 | D5: 629076.38 | E5: 606371
