Workbook

Sheet Assumptions
A2: My Approach
A9: Assumption | B9: Rationale
A10: Bottom 5% of rental volume removed ( Final Sample =263 Locations) | B10: Reduce noise from very small locations
A11: Focused on Product 4 | B11: Largest median attachment gap
A12: +5 pp and +10 pp scenarios | B12: Conservative improvement below benchmark
A13: Scenario analysis | B13: Illustrative, not predictive

Sheet Opportunity Ranking
A2: Outputs were generated using R
A3: Similar tables were constructed for all 5 penetrations for high and low percentages
A4: Top/Bottom 10 rankings shown for Product 4.
A5: Recurring Location Frequency summarizes appearances across all five ancillary products
A7: Product 4 (Low Penetration) | I7: Recurring Locations Across All Products
A9: Rank | B9: Checkout Loc. | C9: Product 4 Pentration | D9: Walkup/No Reservation % | E9: Counter Bypass % | I9: Location | J9: # of Appearences
A10: 1 | B10: Location 23 | C10: 0 | D10: 0.0324 | E10: 0.458 | I10: 260 | J10: 3
A11: 2 | B11: Location 25 | C11: 0 | D11: 0.0231 | E11: 0.54 | I11: 137 | J11: 2
A12: 3 | B12: Location 28 | C12: 0 | D12: 0.0247 | E12: 0.432 | I12: 224 | J12: 2
A13: 4 | B13: Location 79 | C13: 0 | D13: 0.0564 | E13: 0.449 | I13: 232 | J13: 2
A14: 5 | B14: Location 21 | C14: 0.0001 | D14: 0.0425 | E14: 0.485 | I14: 248 | J14: 2
A15: 6 | B15: Location 75 | C15: 0.0001 | D15: 0.0555 | E15: 0.552 | I15: 254 | J15: 2
A16: 7 | B16: Location 100 | C16: 0.0001 | D16: 0.0265 | E16: 0.539 | I16: 263 | J16: 2
A17: 8 | B17: Location 117 | C17: 0.0001 | D17: 0.0329 | E17: 0.375 | I17: 100 | J17: 1
A18: 9 | B18: Location 47 | C18: 0.0002 | D18: 0.0324 | E18: 0.443 | I18: 105 | J18: 1
A19: 10 | B19: Location 91 | C19: 0.0002 | D19: 0.0388 | E19: 0.438 | I19: 117 | J19: 1
A21: Product 4 (HIgh Penetration)
A23: Rank | B23: Checkout Loc. | C23: Product 4 Pentration | D23: Walkup/No Reservation % | E23: Counter Bypass % | I23: Location | J23: # of Appearences
A24: 1 | B24: Location 41 | C24: 0.194 | D24: 0.0349 | E24: 0.44 | I24: 7 | J24: 4
A25: 2 | B25: Location 89 | C25: 0.217 | D25: 0.0433 | E25: 0.261 | I25: 2 | J25: 3
A26: 3 | B26: Location 6 | C26: 0.218 | D26: 0.0214 | E26: 0.509 | I26: 233 | J26: 3
A27: 4 | B27: Location 11 | C27: 0.246 | D27: 0.0466 | E27: 0.395 | I27: 8 | J27: 3
A28: 5 | B28: Location 10 | C28: 0.253 | D28: 0.0148 | E28: 0.482 | I28: 1 | J28: 2
A29: 6 | B29: Location 8 | C29: 0.26 | D29: 0.023 | E29: 0.525 | I29: 157 | J29: 2
A30: 7 | B30: Location 5 | C30: 0.281 | D30: 0.0442 | E30: 0.52 | I30: 16 | J30: 2
A31: 8 | B31: Location 16 | C31: 0.294 | D31: 0.043 | E31: 0.468 | I31: 192 | J31: 2
A32: 9 | B32: Location 1 | C32: 0.43 | D32: 0.0517 | E32: 0.395 | I32: 248 | J32: 2
A33: 10 | B33: Location 7 | C33: 0.598 | D33: 0.0375 | E33: 0.305 | I33: 251 | J33: 2

Sheet Benchmark Comparison
A2: Key Differences Between High and Low Performing Locations
A5: Low Performer | B5: P1 | C5: P2 | D5: P3 | E5: P4 | F5: P5
A6: Location 260 | B6: =_xlfn.XLOOKUP(A6,'RAW DATA'!A:A,'RAW DATA'!T:T) -> 0.0249 | C6: =_xlfn.XLOOKUP(A6,'RAW DATA'!A:A,'RAW DATA'!W:W) -> 0.0084 | D6: =_xlfn.XLOOKUP(A6,'RAW DATA'!A:A,'RAW DATA'!Z:Z) -> 0.0132 | E6: =_xlfn.XLOOKUP(A6,'RAW DATA'!A:A,'RAW DATA'!AC:AC) -> 0.005 | F6: =_xlfn.XLOOKUP(A6,'RAW DATA'!A:A,'RAW DATA'!AF:AF) -> 0.0031
A7: Location 137 | B7: =_xlfn.XLOOKUP(A7,'RAW DATA'!A:A,'RAW DATA'!T:T) -> 0.0505 | C7: =_xlfn.XLOOKUP(A7,'RAW DATA'!A:A,'RAW DATA'!W:W) -> 0.0143 | D7: =_xlfn.XLOOKUP(A7,'RAW DATA'!A:A,'RAW DATA'!Z:Z) -> 0.0222 | E7: =_xlfn.XLOOKUP(A7,'RAW DATA'!A:A,'RAW DATA'!AC:AC) -> 0.0004 | F7: =_xlfn.XLOOKUP(A7,'RAW DATA'!A:A,'RAW DATA'!AF:AF) -> 0.0131
A8: Location 224 | B8: =_xlfn.XLOOKUP(A8,'RAW DATA'!A:A,'RAW DATA'!T:T) -> 0.0509 | C8: =_xlfn.XLOOKUP(A8,'RAW DATA'!A:A,'RAW DATA'!W:W) -> 0.0192 | D8: =_xlfn.XLOOKUP(A8,'RAW DATA'!A:A,'RAW DATA'!Z:Z) -> 0.0153 | E8: =_xlfn.XLOOKUP(A8,'RAW DATA'!A:A,'RAW DATA'!AC:AC) -> 0.011 | F8: =_xlfn.XLOOKUP(A8,'RAW DATA'!A:A,'RAW DATA'!AF:AF) -> 0.003
A10: High Performers | B10: P1 | C10: P2 | D10: P3 | E10: P4 | F10: P5
A11: Location 7 | B11: =_xlfn.XLOOKUP(A11,'RAW DATA'!A:A,'RAW DATA'!T:T) -> 0.0727 | C11: =_xlfn.XLOOKUP(A11,'RAW DATA'!A:A,'RAW DATA'!W:W) -> 0.0969 | D11: =_xlfn.XLOOKUP(A11,'RAW DATA'!A:A,'RAW DATA'!Z:Z) -> 0.1905 | E11: =_xlfn.XLOOKUP(A11,'RAW DATA'!A:A,'RAW DATA'!AC:AC) -> 0.598 | F11: =_xlfn.XLOOKUP(A11,'RAW DATA'!A:A,'RAW DATA'!AF:AF) -> 0.2699
A12: Location 157 | B12: =_xlfn.XLOOKUP(A12,'RAW DATA'!A:A,'RAW DATA'!T:T) -> 0.1277 | C12: =_xlfn.XLOOKUP(A12,'RAW DATA'!A:A,'RAW DATA'!W:W) -> 0.3092 | D12: =_xlfn.XLOOKUP(A12,'RAW DATA'!A:A,'RAW DATA'!Z:Z) -> 0.2306 | E12: =_xlfn.XLOOKUP(A12,'RAW DATA'!A:A,'RAW DATA'!AC:AC) -> 0.0392 | F12: =_xlfn.XLOOKUP(A12,'RAW DATA'!A:A,'RAW DATA'!AF:AF) -> 0.0107
A13: Location 233 | B13: =_xlfn.XLOOKUP(A13,'RAW DATA'!A:A,'RAW DATA'!T:T) -> 0.2646 | C13: =_xlfn.XLOOKUP(A13,'RAW DATA'!A:A,'RAW DATA'!W:W) -> 0.0979 | D13: =_xlfn.XLOOKUP(A13,'RAW DATA'!A:A,'RAW DATA'!Z:Z) -> 0.1575 | E13: =_xlfn.XLOOKUP(A13,'RAW DATA'!A:A,'RAW DATA'!AC:AC) -> 0.1544 | F13: =_xlfn.XLOOKUP(A13,'RAW DATA'!A:A,'RAW DATA'!AF:AF) -> 0.0179
A16: High- Low Performers | C16: Median Prodcut Gap (percentage points) | D16: 0.1752 | E16: 0.1494
C17: Mean Product Gap (percentage points) | D17: 0.17596667 | E17: 0.2584
A21: Checkout Loc. | B21: Number of Rentals | C21: % of Avis Transactions | D21: Commercial Transactions | E21: Leisure Transactions | F21: % CORE | G21: % EV | H21: % PICKUP | I21: % SPECIALTY | J21: % SUV | K21: % VAN | L21: Counter Bypass % | M21: Walkup/No Reservation %
A22: Location 260 | B22: 3342 | C22: 1 | D22: 2839 | E22: 503 | F22: 0.8537 | G22: 0 | H22: 0.0003 | I22: 0.0009 | J22: 0.102 | K22: 0.0431 | L22: 0.8121 | M22: 0.0081
A23: Location 137 | B23: 22905 | C23: 0.4099 | D23: 10484 | E23: 12421 | F23: 0.7916 | G23: 0.0074 | H23: 0.0141 | I23: 0.0436 | J23: 0.104 | K23: 0.0393 | L23: 0.3272 | M23: 0.0406
A24: Location 224 | B24: 5653 | C24: 0.5946 | D24: 2119 | E24: 3534 | F24: 0.7674 | G24: 0.0177 | H24: 0.0018 | I24: 0.0513 | J24: 0.13 | K24: 0.0318 | L24: 0.3333 | M24: 0.0368
A26: Location 7 | B26: 392991 | C26: 0.5754 | D26: 72162 | E26: 320829 | F26: 0.6107 | G26: 0.0216 | H26: 0.0055 | I26: 0.0618 | J26: 0.2217 | K26: 0.0787 | L26: 0.3054 | M26: 0.0375
A27: Location 157 | B27: 15145 | C27: 1 | D27: 998 | E27: 14147 | F27: 0.6632 | G27: 0.0085 | H27: 0.0039 | I27: 0.0153 | J27: 0.1794 | K27: 0.1297 | L27: 0.1076 | M27: 0.0929
A28: Location 233 | B28: 4900 | C28: 0.6069 | D28: 777 | E28: 4123 | F28: 0.6839 | G28: 0.0016 | H28: 0.0045 | I28: 0.0649 | J28: 0.1751 | K28: 0.07 | L28: 0.2598 | M28: 0.0792

Sheet Revenue Scenario
A8: Checkout Loc. | B8: Number of Rentals | C8: Length of Rental (in Days) | D8: Product 4 Revenue | E8: Product 4 Penetration | F8: Product 4 Rate per Sold Day | G8: My Product 4 Revenue
A9: Location 260 | B9: 3342 | C9: 4.41 | D9: 1037 | E9: 0.005 | F9: 13.95 | G9: =F9*E9*C9*B9 -> 1027.9908
A14: Checkout Loc. | B14: Scenario | C14: P4 Penetration | D14: Actual Revenue | E14: Projected Revenue | F14: Incremental Revenue
A15: 260 | B15: Current | C15: 0.005 | D15: 1037 | E15: 1037 | F15: —
A16: 260 | B16: 5 pp (conservative) | C16: 5.50% | D16: 1037 | E16: =C9*C16*F9*B9 -> 11307.899 | F16: =E16-E15 -> 10270.899
A17: 260 | B17: 10 pp (moderate) | C17: 10.50% | D17: 1037 | E17: =B9*C17*F9*C9 -> 21587.808 | F17: =E17-E15 -> 20550.808

Sheet RAW DATA
C1: Brand | F1: Origin | H1: Customer Segment | J1: Car Type | S1: Counter Sales/Ancillary Sales Data
A2: Checkout Location Code | B2: Number of Rentals | C2: % of Avis Transactions | D2: % of Budget Transactions | E2: % of Payless Transactions | F2: Domestic Transactions | G2: Inbound Transactions | H2: Commercial Transactions | I2: Leisure Transactions | J2: % CORE | K2: % EV | L2: % PICKUP | M2: % SPECIALTY | N2: % SUV | O2: % VAN | P2: Counter Bypass % | Q2: Walkup/No Reservation % | R2: Length of Rental (in Days) | S2: Product 1 Revenue | T2: Product 1 Penetration | U2: Product 1 Rate per Sold Day | V2: Product 2 Revenue | W2: Product 2 Penetration | X2: Product 2 Rate per Sold Day | Y2: Product 3 Revenue | Z2: Product 3 Penetration | AA2: Product 3 Rate per Sold Day | AB2: Product 4 Revenue | AC2: Product 4 Penetration | AD2: Product 4 Rate per Sold Day | AE2: Product 5 Revenue | AF2: Product 5 Penetration | AG2: Product 5 Rate per Sold Day
A3: Location 1 | B3: 800283 | C3: 0.5163 | D3: 0.4705 | E3: 0.0132 | F3: 663273 | G3: 137010 | H3: 200909 | I3: 599374 | J3: 0.6092 | K3: 0.0269 | L3: 0.0085 | M3: 0.0433 | N3: 0.2085 | O3: 0.1036 | P3: 0.3953 | Q3: 0.0517 | R3: 4.98 | S3: 16015071 | T3: 0.0957 | U3: 41.98 | V3: 5575719 | W3: 0.0754 | X3: 18.55 | Y3: 2328861 | Z3: 0.0676 | AA3: 8.64 | AB3: 21038826 | AC3: 0.4301 | AD3: 12.27 | AE3: 8340933 | AF3: 0.232 | AG3: 9.02
A4: Location 2 | B4: 594242 | C4: 0.6158 | D4: 0.3517 | E4: 0.0325 | F4: 488545 | G4: 105697 | H4: 201263 | I4: 392979 | J4: 0.6727 | K4: 0.0519 | L4: 0.0134 | M4: 0.069 | N4: 0.1491 | O4: 0.044 | P4: 0.4451 | Q4: 0.0145 | R4: 4.47 | S4: 10220696 | T4: 0.1155 | U4: 33.31 | V4: 5722793 | W4: 0.1311 | X4: 16.43 | Y4: 4198254 | Z4: 0.1807 | AA4: 8.75 | AB4: 3697070 | AC4: 0.1201 | AD4: 11.59 | AE4: 5737212 | AF4: 0.1584 | AG4: 13.63
A5: Location 3 | B5: 571216 | C5: 0.5507 | D5: 0.4149 | E5: 0.0345 | F5: 552698 | G5: 18518 | H5: 205657 | I5: 365559 | J5: 0.6 | K5: 0.0309 | L5: 0.0294 | M5: 0.0547 | N5: 0.2537 | O5: 0.0313 | P5: 0.4942 | Q5: 0.0168 | R5: 3.83 | S5: 9391543 | T5: 0.0988 | U5: 43.51 | V5: 2408080 | W5: 0.0501 | X5: 21.98 | Y5: 1144434 | Z5: 0.0575 | AA5: 9.11 | AB5: 4364174 | AC5: 0.163 | AD5: 12.25 | AE5: 4144535 | AF5: 0.1534 | AG5: 12.37
A6: Location 4 | B6: 528774 | C6: 0.5379 | D6: 0.3902 | E6: 0.0719 | F6: 508432 | G6: 20342 | H6: 185830 | I6: 342944 | J6: 0.6178 | K6: 0.0504 | L6: 0.0124 | M6: 0.0724 | N6: 0.2045 | O6: 0.0424 | P6: 0.4603 | Q6: 0.0249 | R6: 4.07 | S6: 9658629 | T6: 0.1084 | U6: 41.41 | V6: 1907658 | W6: 0.0424 | X6: 20.89 | Y6: 799586 | Z6: 0.0412 | AA6: 9.02 | AB6: 65509 | AC6: 0.0024 | AD6: 12.75 | AE6: 3104480 | AF6: 0.1183 | AG6: 12.19
A7: Location 5 | B7: 450581 | C7: 0.6584 | D7: 0.3139 | E7: 0.0277 | F7: 424505 | G7: 26076 | H7: 208817 | I7: 241764 | J7: 0.7036 | K7: 0.03 | L7: 0.0228 | M7: 0.061 | N7: 0.1471 | O7: 0.0356 | P7: 0.5198 | Q7: 0.0442 | R7: 3.51 | S7: 6341246 | T7: 0.0942 | U7: 42.57 | V7: 2642410 | W7: 0.0803 | X7: 20.81 | Y7: 1048603 | Z7: 0.0714 | AA7: 9.3 | AB7: 6077627 | AC7: 0.2808 | AD7: 13.69 | AE7: 2434746 | AF7: 0.1264 | AG7: 12.18
A8: Location 6 | B8: 410451 | C8: 0.6447 | D8: 0.3553 | E8: 0 | F8: 344086 | G8: 66365 | H8: 171508 | I8: 238943 | J8: 0.7009 | K8: 0.0457 | L8: 0.0156 | M8: 0.0592 | N8: 0.1407 | O8: 0.0379 | P8: 0.5088 | Q8: 0.0214 | R8: 4.59 | S8: 4617389 | T8: 0.0739 | U8: 33.2 | V8: 1995409 | W8: 0.0643 | X8: 16.47 | Y8: 864763 | Z8: 0.0531 | AA8: 8.64 | AB8: 5035438 | AC8: 0.2182 | AD8: 12.26 | AE8: 3047498 | AF8: 0.1013 | AG8: 15.98
A9: Location 7 | B9: 392991 | C9: 0.5754 | D9: 0.4185 | E9: 0.0061 | F9: 232191 | G9: 160800 | H9: 72162 | I9: 320829 | J9: 0.6107 | K9: 0.0216 | L9: 0.0055 | M9: 0.0618 | N9: 0.2217 | O9: 0.0787 | P9: 0.3054 | Q9: 0.0375 | R9: 5.19 | S9: 6164283 | T9: 0.0727 | U9: 41.56 | V9: 3728640 | W9: 0.0969 | X9: 18.86 | Y9: 3360430 | Z9: 0.1905 | AA9: 8.64 | AB9: 14554029 | AC9: 0.598 | AD9: 11.93 | AE9: 4161703 | AF9: 0.2699 | AG9: 7.56
A10: Location 8 | B10: 378538 | C10: 0.6321 | D10: 0.3463 | E10: 0.0216 | F10: 346824 | G10: 31714 | H10: 157606 | I10: 220932 | J10: 0.6822 | K10: 0.0286 | L10: 0.0135 | M10: 0.0649 | N10: 0.1681 | O10: 0.0427 | P10: 0.5252 | Q10: 0.023 | R10: 3.47 | S10: 4811379 | T10: 0.0877 | U10: 41.78 | V10: 1308448 | W10: 0.051 | X10: 19.55 | Y10: 1245995 | Z10: 0.1016 | AA10: 9.34 | AB10: 4177359 | AC10: 0.2603 | AD10: 12.23 | AE10: 3797907 | AF10: 0.1965 | AG10: 14.72
A11: Location 9 | B11: 371306 | C11: 0.5856 | D11: 0.3752 | E11: 0.0391 | F11: 354225 | G11: 17081 | H11: 156987 | I11: 214319 | J11: 0.6949 | K11: 0.0406 | L11: 0.0274 | M11: 0.0563 | N11: 0.1286 | O11: 0.0522 | P11: 0.461 | Q11: 0.0275 | R11: 4.5 | S11: 6647499 | T11: 0.1029 | U11: 38.67 | V11: 2390154 | W11: 0.091 | X11: 15.72 | Y11: 764385 | Z11: 0.0515 | AA11: 8.89 | AB11: 1526231 | AC11: 0.0804 | AD11: 11.36 | AE11: 2174223 | AF11: 0.0789 | AG11: 16.49
A12: Location 10 | B12: 368051 | C12: 0.5792 | D12: 0.4078 | E12: 0.013 | F12: 334981 | G12: 33070 | H12: 132733 | I12: 235318 | J12: 0.6929 | K12: 0.0145 | L12: 0.0149 | M12: 0.0533 | N12: 0.182 | O12: 0.0425 | P12: 0.4823 | Q12: 0.0148 | R12: 4.3 | S12: 6626531 | T12: 0.1119 | U12: 37.41 | V12: 2062361 | W12: 0.0677 | X12: 19.25 | Y12: 1215292 | Z12: 0.0849 | AA12: 9.05 | AB12: 5849853 | AC12: 0.2534 | AD12: 14.59 | AE12: 2597552 | AF12: 0.1242 | AG12: 13.22
A13: Location 11 | B13: 357616 | C13: 0.4969 | D13: 0.4955 | E13: 0.0076 | F13: 304350 | G13: 53266 | H13: 81952 | I13: 275664 | J13: 0.6027 | K13: 0.0255 | L13: 0.0076 | M13: 0.061 | N13: 0.226 | O13: 0.0772 | P13: 0.3952 | Q13: 0.0466 | R13: 4.48 | S13: 4980069 | T13: 0.0758 | U13: 40.96 | V13: 2445987 | W13: 0.0805 | X13: 18.94 | Y13: 342489 | Z13: 0.0239 | AA13: 8.95 | AB13: 5016547 | AC13: 0.2456 | AD13: 12.74 | AE13: 1795200 | AF13: 0.1181 | AG13: 9.48
A14: Location 12 | B14: 355996 | C14: 0.5079 | D14: 0.4795 | E14: 0.0127 | F14: 329927 | G14: 26069 | H14: 95783 | I14: 260213 | J14: 0.6312 | K14: 0.0274 | L14: 0.0112 | M14: 0.0464 | N14: 0.2194 | O14: 0.0642 | P14: 0.4361 | Q14: 0.0231 | R14: 4.73 | S14: 6794008 | T14: 0.0951 | U14: 42.43 | V14: 2424339 | W14: 0.0773 | X14: 18.63 | Y14: 506332 | Z14: 0.0341 | AA14: 8.82 | AB14: 3442174 | AC14: 0.1628 | AD14: 12.56 | AE14: 2828629 | AF14: 0.1805 | AG14: 9.31
... A21: Location 19 | B21: 259981 | C21: 0.5569 | D21: 0.4431 | E21: 0 | F21: 247812 | G21: 12169 | H21: 98322 | I21: 161659 | J21: 0.7137 | K21: 0.0176 | L21: 0.0287 | M21: 0.0512 | N21: 0.1524 | O21: 0.0364 | P21: 0.4846 | Q21: 0.0253 | R21: 3.7 | S21: 3330523 | T21: 0.0923 | U21: 37.52 | V21: 1088710 | W21: 0.053 | X21: 21.36 | Y21: 274868 | Z21: 0.0307 | AA21: 9.31 | AB21: 237110 | AC21: 0.0209 | AD21: 11.8 | AE21: 1076311 | AF21: 0.0879 | AG21: 12.73
A22: Location 20 | B22: 256962 | C22: 0.3919 | D22: 0.5732 | E22: 0.0349 | F22: 237915 | G22: 19047 | H22: 65928 | I22: 191034 | J22: 0.5884 | K22: 0.029 | L22: 0.1004 | M22: 0.0828 | N22: 0.1164 | O22: 0.0829 | P22: 0.3547 | Q22: 0.0326 | R22: 5.11 | S22: 7573626 | T22: 0.1734 | U22: 33.26 | V22: 1300842 | W22: 0.0639 | X22: 15.5 | Y22: 589900 | Z22: 0.0501 | AA22: 8.97 | AB22: 0 | AE22: 1169195 | AF22: 0.0653 | AG22: 13.62
A23: Location 21 | B23: 255668 | C23: 0.9142 | D23: 0 | E23: 0.0858 | F23: 224370 | G23: 31298 | H23: 91743 | I23: 163925 | J23: 0.6186 | K23: 0.0436 | L23: 0.0224 | M23: 0.0821 | N23: 0.1792 | O23: 0.054 | P23: 0.4854 | Q23: 0.0425 | R23: 4.13 | S23: 4726374 | T23: 0.1315 | U23: 34.01 | V23: 1429805 | W23: 0.0725 | X23: 18.65 | Y23: 1075564 | Z23: 0.1146 | AA23: 8.88 | AB23: 2047 | AC23: 0.0001 | AD23: 20.27 | AE23: 938128 | AF23: 0.0621 | AG23: 14.28
A24: Location 22 | B24: 239141 | C24: 0.5473 | D24: 0.418 | E24: 0.0346 | F24: 232244 | G24: 6897 | H24: 97766 | I24: 141375 | J24: 0.7221 | K24: 0.019 | L24: 0.0214 | M24: 0.0517 | N24: 0.1474 | O24: 0.0384 | P24: 0.4721 | Q24: 0.0201 | R24: 3.82 | S24: 2981528 | T24: 0.0889 | U24: 36.75 | V24: 586260 | W24: 0.0311 | X24: 20.67 | Y24: 344163 | Z24: 0.0407 | AA24: 9.27 | AB24: 70812 | AC24: 0.0065 | AD24: 11.88 | AE24: 1010778 | AF24: 0.0865 | AG24: 12.81
A25: Location 23 | B25: 238963 | C25: 0.5623 | D25: 0.4128 | E25: 0.0248 | F25: 230854 | G25: 8109 | H25: 89589 | I25: 149374 | J25: 0.6758 | K25: 0.0092 | L25: 0.018 | M25: 0.05 | N25: 0.1903 | O25: 0.0568 | P25: 0.4584 | Q25: 0.0324 | R25: 3.49 | S25: 3096096 | T25: 0.0969 | U25: 38.33 | V25: 935219 | W25: 0.0526 | X25: 21.35 | Y25: 334619 | Z25: 0.043 | AA25: 9.34 | AB25: 486 | AC25: 0 | AD25: 15.56 | AE25: 1457315 | AF25: 0.1532 | AG25: 11.42
A26: Location 24 | B26: 229536 | C26: 0.3898 | D26: 0.5465 | E26: 0.0637 | F26: 211903 | G26: 17633 | H26: 47809 | I26: 181727 | J26: 0.5476 | K26: 0.04 | L26: 0.1161 | M26: 0.0639 | N26: 0.1505 | O26: 0.0819 | P26: 0.351 | Q26: 0.0181 | R26: 5.99 | S26: 4275795 | T26: 0.095 | U26: 32.74 | V26: 926378 | W26: 0.0445 | X26: 15.13 | Y26: 718532 | Z26: 0.0591 | AA26: 8.84 | AB26: 0 | AE26: 982057 | AF26: 0.0603 | AG26: 11.84
A27: Location 25 | B27: 223371 | C27: 0.9401 | D27: 0 | E27: 0.0599 | F27: 215711 | G27: 7660 | H27: 106336 | I27: 117035 | J27: 0.7077 | K27: 0.0078 | L27: 0.0253 | M27: 0.0604 | N27: 0.1691 | O27: 0.0296 | P27: 0.5404 | Q27: 0.0231 | R27: 3.85 | S27: 2580355 | T27: 0.0839 | U27: 35.71 | V27: 797272 | W27: 0.0446 | X27: 20.74 | Y27: 322455 | Z27: 0.0415 | AA27: 9.02 | AB27: 336 | AC27: 0 | AD27: 22.43 | AE27: 901122 | AF27: 0.0786 | AG27: 13.31
A28: Location 26 | B28: 218165 | C28: 0.4138 | D28: 0.5704 | E28: 0.0158 | F28: 209793 | G28: 8372 | H28: 39705 | I28: 178460 | J28: 0.6085 | K28: 0.0089 | L28: 0.0097 | M28: 0.0545 | N28: 0.24 | O28: 0.0784 | P28: 0.4128 | Q28: 0.0168 | R28: 5.9 | S28: 3188149 | T28: 0.0644 | U28: 38.47 | V28: 749011 | W28: 0.0314 | X28: 18.56 | Y28: 165437 | Z28: 0.0148 | AA28: 8.7 | AB28: 915922 | AC28: 0.0598 | AD28: 11.91 | AE28: 1662535 | AF28: 0.1597 | AG28: 8.09
A29: Location 27 | B29: 201208 | C29: 0.5589 | D29: 0.4192 | E29: 0.022 | F29: 164086 | G29: 37122 | H29: 35380 | I29: 165828 | J29: 0.62 | K29: 0.0153 | L29: 0.0307 | M29: 0.0655 | N29: 0.1968 | O29: 0.0718 | P29: 0.33 | Q29: 0.0433 | R29: 4.63 | S29: 3182103 | T29: 0.2 | U29: 17.09 | V29: 1794937 | W29: 0.098 | X29: 19.67 | Y29: 466802 | Z29: 0.0558 | AA29: 8.98 | AB29: 3913312 | AC29: 0.1672 | AD29: 25.13 | AE29: 791004 | AF29: 0.062 | AG29: 13.71
A30: Location 28 | B30: 201177 | C30: 0.5549 | D30: 0.3975 | E30: 0.0476 | F30: 197659 | G30: 3518 | H30: 66594 | I30: 134583 | J30: 0.7018 | K30: 0.0288 | L30: 0.0144 | M30: 0.0764 | N30: 0.136 | O30: 0.0426 | P30: 0.432 | Q30: 0.0247 | R30: 4.28 | S30: 2762474 | T30: 0.0858 | U30: 37.37 | V30: 666467 | W30: 0.0409 | X30: 18.91 | Y30: 247697 | Z30: 0.0321 | AA30: 8.97 | AB30: 48 | AC30: 0 | AD30: 23.84 | AE30: 981515 | AF30: 0.0812 | AG30: 14.04
A31: Location 29 | B31: 200435 | C31: 0.6317 | D31: 0.3437 | E31: 0.0246 | F31: 192777 | G31: 7658 | H31: 84875 | I31: 115560 | J31: 0.686 | K31: 0.0416 | L31: 0.0158 | M31: 0.0517 | N31: 0.1616 | O31: 0.0432 | P31: 0.4914 | Q31: 0.0281 | R31: 3.76 | S31: 2595115 | T31: 0.0872 | U31: 39.47 | V31: 835379 | W31: 0.0542 | X31: 20.43 | Y31: 346295 | Z31: 0.0505 | AA31: 9.1 | AB31: 1922062 | AC31: 0.192 | AD31: 13.27 | AE31: 864875 | AF31: 0.1068 | AG31: 10.73
A32: Location 30 | B32: 200208 | C32: 0.5402 | D32: 0.4435 | E32: 0.0163 | F32: 194806 | G32: 5402 | H32: 70412 | I32: 129796 | J32: 0.7257 | K32: 0.0164 | L32: 0.0307 | M32: 0.0487 | N32: 0.1311 | O32: 0.0474 | P32: 0.4564 | Q32: 0.0152 | R32: 3.71 | S32: 2278934 | T32: 0.0805 | U32: 38.1 | V32: 780746 | W32: 0.0494 | X32: 21.27 | Y32: 170357 | Z32: 0.0249 | AA32: 9.2 | AB32: 294798 | AC32: 0.033 | AD32: 12 | AE32: 981947 | AF32: 0.1016 | AG32: 13
A33: Location 31 | B33: 192178 | C33: 0.6188 | D33: 0.3812 | E33: 0 | F33: 177519 | G33: 14659 | H33: 79874 | I33: 112304 | J33: 0.7035 | K33: 0.0195 | L33: 0.0291 | M33: 0.041 | N33: 0.1592 | O33: 0.0477 | P33: 0.4842 | Q33: 0.052 | R33: 4.21 | S33: 3450407 | T33: 0.1157 | U33: 36.85 | V33: 1198144 | W33: 0.0816 | X33: 18.15 | Y33: 584130 | Z33: 0.0824 | AA33: 8.76 | AB33: 1969404 | AC33: 0.099 | AD33: 24.59 | AE33: 632461 | AF33: 0.0654 | AG33: 11.95
A34: Location 32 | B34: 191061 | C34: 0.4619 | D34: 0.4975 | E34: 0.0407 | F34: 188327 | G34: 2734 | H34: 58896 | I34: 132165 | J34: 0.6483 | K34: 0.0732 | L34: 0.0245 | M34: 0.0795 | N34: 0.1369 | O34: 0.0375 | P34: 0.4117 | Q34: 0.029 | R34: 4.02 | S34: 3980842 | T34: 0.1511 | U34: 34.32 | V34: 672693 | W34: 0.0524 | X34: 16.74 | Y34: 226033 | Z34: 0.0315 | AA34: 9.34 | AB34: 104821 | AC34: 0.0096 | AD34: 14.2 | AE34: 904708 | AF34: 0.058 | AG34: 20.32
A35: Location 33 | B35: 188522 | C35: 0.5432 | D35: 0.4315 | E35: 0.0253 | F35: 181220 | G35: 7302 | H35: 46934 | I35: 141588 | J35: 0.6377 | K35: 0.0208 | L35: 0.03 | M35: 0.0562 | N35: 0.1804 | O35: 0.075 | P35: 0.4038 | Q35: 0.0273 | R35: 3.52 | S35: 2163651 | T35: 0.18 | U35: 18.11 | V35: 956223 | W35: 0.0716 | X35: 20.13 | Y35: 315707 | Z35: 0.0508 | AA35: 9.36 | AB35: 1994689 | AC35: 0.1096 | AD35: 27.42 | AE35: 501235 | AF35: 0.0488 | AG35: 15.49
A36: Location 34 | B36: 186005 | C36: 0.684 | D36: 0.2833 | E36: 0.0327 | F36: 182456 | G36: 3549 | H36: 101457 | I36: 84548 | J36: 0.7448 | K36: 0.04 | L36: 0.0208 | M36: 0.0432 | N36: 0.1123 | O36: 0.0391 | P36: 0.5909 | Q36: 0.016 | R36: 3.76 | S36: 1761476 | T36: 0.0782 | U36: 32.22 | V36: 824900 | W36: 0.0716 | X36: 16.48 | Y36: 198516 | Z36: 0.0309 | AA36: 9.2 | AB36: 251216 | AC36: 0.0279 | AD36: 12.9 | AE36: 415888 | AF36: 0.0321 | AG36: 18.57
A37: Location 35 | B37: 185162 | C37: 0.5614 | D37: 0.4386 | E37: 0 | F37: 183501 | G37: 1661 | H37: 68005 | I37: 117157 | J37: 0.69 | K37: 0.0173 | L37: 0.0274 | M37: 0.0517 | N37: 0.1659 | O37: 0.0477 | P37: 0.4752 | Q37: 0.0316 | R37: 3.82 | S37: 2355284 | T37: 0.0894 | U37: 37.28 | V37: 849489 | W37: 0.066 | X37: 18.23 | Y37: 489570 | Z37: 0.0713 | AA37: 9.72 | AB37: 1404859 | AC37: 0.074 | AD37: 26.86 | AE37: 749118 | AF37: 0.079 | AG37: 13.42
A38: Location 36 | B38: 179643 | C38: 0.5127 | D38: 0.4771 | E38: 0.0102 | F38: 175609 | G38: 4034 | H38: 48525 | I38: 131118 | J38: 0.6277 | K38: 0.0224 | L38: 0.0116 | M38: 0.0593 | N38: 0.2243 | O38: 0.0548 | P38: 0.4271 | Q38: 0.0339 | R38: 5.29 | S38: 2267890 | T38: 0.0644 | U38: 37.01 | V38: 661224 | W38: 0.0372 | X38: 18.69 | Y38: 136857 | Z38: 0.0165 | AA38: 8.71 | AB38: 1013241 | AC38: 0.0869 | AD38: 12.26 | AE38: 804667 | AF38: 0.092 | AG38: 9.2
... A43: Location 41 | B43: 164256 | C43: 0.456 | D43: 0.4599 | E43: 0.0841 | F43: 163482 | G43: 774 | H43: 54359 | I43: 109897 | J43: 0.6807 | K43: 0.0315 | L43: 0.0326 | M43: 0.0619 | N43: 0.1509 | O43: 0.0425 | P43: 0.4403 | Q43: 0.0349 | R43: 3.32 | S43: 2755474 | T43: 0.1164 | U43: 43.42 | V43: 800830 | W43: 0.0709 | X43: 20.72 | Y43: 373713 | Z43: 0.0705 | AA43: 9.73 | AB43: 1502475 | AC43: 0.194 | AD43: 14.21 | AE43: 793851 | AF43: 0.1129 | AG43: 12.89
A44: Location 42 | B44: 153494 | C44: 0.3741 | D44: 0.597 | E44: 0.0288 | F44: 147219 | G44: 6275 | H44: 31303 | I44: 122191 | J44: 0.6365 | K44: 0.0071 | L44: 0.0824 | M44: 0.0465 | N44: 0.1552 | O44: 0.0722 | P44: 0.328 | Q44: 0.0169 | R44: 5.59 | S44: 3847300 | T44: 0.1356 | U44: 33.04 | V44: 446731 | W44: 0.0336 | X44: 15.47 | Y44: 406812 | Z44: 0.0534 | AA44: 8.87 | AB44: 0 | AE44: 1045399 | AF44: 0.0928 | AG44: 13.12
A45: Location 43 | B45: 147826 | C45: 0.3826 | D45: 0.572 | E45: 0.0454 | F45: 135738 | G45: 12088 | H45: 29297 | I45: 118529 | J45: 0.5589 | K45: 0.0002 | L45: 0.1371 | M45: 0.0548 | N45: 0.1831 | O45: 0.0659 | P45: 0.3333 | Q45: 0.0134 | R45: 5.94 | S45: 2697290 | T45: 0.0925 | U45: 33.22 | V45: 733278 | W45: 0.0549 | X45: 15.21 | Y45: 291729 | Z45: 0.038 | AA45: 8.75 | AB45: 0 | AE45: 909684 | AF45: 0.0812 | AG45: 12.76
A46: Location 44 | B46: 147802 | C46: 0.9172 | D46: 0 | E46: 0.0828 | F46: 145036 | G46: 2766 | H46: 67341 | I46: 80461 | J46: 0.7168 | K46: 0.0307 | L46: 0.0203 | M46: 0.045 | N46: 0.1535 | O46: 0.0338 | P46: 0.5083 | Q46: 0.0336 | R46: 3.45 | S46: 2073687 | T46: 0.0943 | U46: 43.15 | V46: 665031 | W46: 0.0733 | X46: 17.8 | Y46: 425207 | Z46: 0.0874 | AA46: 9.54 | AB46: 254040 | AC46: 0.0397 | AD46: 12.55 | AE46: 654453 | AF46: 0.1064 | AG46: 12.07
A47: Location 45 | B47: 140480 | C47: 0.5774 | D47: 0.3691 | E47: 0.0535 | F47: 137724 | G47: 2756 | H47: 57753 | I47: 82727 | J47: 0.6756 | K47: 0.0202 | L47: 0.0161 | M47: 0.0612 | N47: 0.1871 | O47: 0.0398 | P47: 0.4796 | Q47: 0.0195 | R47: 3.72 | S47: 1607962 | T47: 0.0801 | U47: 38.42 | V47: 490516 | W47: 0.0515 | X47: 18.24 | Y47: 210237 | Z47: 0.0437 | AA47: 9.21 | AB47: 73817 | AC47: 0.0114 | AD47: 12.4 | AE47: 556961 | AF47: 0.0723 | AG47: 14.73
A48: Location 46 | B48: 135602 | C48: 0.5886 | D48: 0.4094 | E48: 0.0019 | F48: 132275 | G48: 3327 | H48: 48698 | I48: 86904 | J48: 0.6662 | K48: 0.0236 | L48: 0.0162 | M48: 0.0713 | N48: 0.1812 | O48: 0.0416 | P48: 0.4478 | Q48: 0.0337 | R48: 3.79 | S48: 1724942 | T48: 0.0884 | U48: 37.95 | V48: 523810 | W48: 0.0529 | X48: 19.28 | Y48: 138365 | Z48: 0.0287 | AA48: 9.37 | AB48: 101082 | AC48: 0.011 | AD48: 17.83 | AE48: 385198 | AF48: 0.0501 | AG48: 14.96
A49: Location 47 | B49: 132629 | C49: 0.5044 | D49: 0.4668 | E49: 0.0287 | F49: 127800 | G49: 4829 | H49: 47334 | I49: 85295 | J49: 0.7003 | K49: 0.012 | L49: 0.0153 | M49: 0.0573 | N49: 0.1699 | O49: 0.0451 | P49: 0.4427 | Q49: 0.0324 | R49: 3.71 | S49: 1471613 | T49: 0.0763 | U49: 39.21 | V49: 329952 | W49: 0.0327 | X49: 20.53 | Y49: 74851 | Z49: 0.017 | AA49: 8.96 | AB49: 2063 | AC49: 0.0002 | AD49: 21.65 | AE49: 430974 | AF49: 0.0713 | AG49: 12.29
A50: Location 48 | B50: 131723 | C50: 0.6338 | D50: 0.3662 | E50: 0 | F50: 127682 | G50: 4041 | H50: 58727 | I50: 72996 | J50: 0.7071 | K50: 0.0211 | L50: 0.0158 | M50: 0.0465 | N50: 0.1629 | O50: 0.0466 | P50: 0.4935 | Q50: 0.0346 | R50: 3.94 | S50: 2165300 | T50: 0.1026 | U50: 40.73 | V50: 555009 | W50: 0.0522 | X50: 20.52 | Y50: 283239 | Z50: 0.0568 | AA50: 9.61 | AB50: 1880952 | AC50: 0.1574 | AD50: 23.06 | AE50: 877535 | AF50: 0.1001 | AG50: 16.92
...
